Workbook

Sheet Final Calculation Sheet
B1: MSTC LIMITED - COMBINED BID SHEET (Auctions 21977, 21978, 21979, 21980)
A3: Quantity | B3: Lot Name | C3: Rate | D3: Bid Sheet | E3: Unit | F3: Lot No. | G3: Buyer | H3: Mat. Value | I3: GST | J3: Mat. Value + GST | K3: TCS | L3: TDS u/s 194(O) | M3: Service Charge to MSTC | N3: TDS u/s 194(H) | O3: Net Service Charge (post TDS 194H) | P3: Service charge to MSTC | Q3: GST TDS Rate | R3: GST TDS | S3: Total Receivables in Cash | T3: Security Deposit (Expected) | U3: Security Deposit (Received) | V3: Date of Receipt | W3: Final Payment (Expected) | X3: Final Payment (Received) | Y3: Date of Receipt | Z3: LPP Expected | AA3: LPP Received | AB3: Date of Recepit of LPP | AC3: Total Received | AD3: Outstanding | AE3: Invoice No. | AF3: SAP Document | AG3: Doc./Invoice Date
A4: 669 | B4: SCRAP COPPER OF T/F WINDING (Oil impregnated paper insulated T/F winding) | C4: 1181 | D4: 21980 | E4: KG | F4: 1763 | G4: AL HAMD TRADE CORPORATION | H4: 790089 | I4: =ROUND(H4*18%,0) | J4: =+H4+I4 | K4: =ROUND((H4+I4)*2%,0) | L4: =H4*0.1% | M4: =H4*2.25%*118% | N4: =H4*2.25%*2% | O4: =M4-N4 | P4: =ROUND(O4+L4,0) | Q4: 0.02 | R4: =ROUND(H4*Q4,0) | S4: =ROUND(H4*117.65%-R4,0) | T4: =ROUND(H4*25%,0) | U4: 197522 | V4: 24.08.2026 | W4: =ROUND(H4*92.65%-R4,0) | X4: 716216 | Y4: 18.08.2026 | Z4: =IF(OR(Y4="",Y4=0),H4*0.0118*CEILING((TODAY()-DATE(2026,8,22))/7,1),IF(DATE(VALUE(RIGHT(Y4,4)),VALUE(MID(Y4,4,2)),VALUE(LEFT(Y4,2)))<=DATE(2026,8,24),0,H4*0.0118*CEILING((DATE(VALUE(RIGHT(Y4,4)),VALUE(MID(Y4,4,2)),VALUE(LEFT(Y4,2)))-DATE(2026,8,22))/7,1))) | AC4: =U4+X4+AA4 | AD4: =S4-AC4 | AE4: DR2640100029 | AF4: 1800003271 | AG4: 24.08.2026
A5: 270 | B5: Scrap of Empty oil drum | C5: 580 | D5: 21977 | E5: NO | F5: 1874 | G5: NATIONAL ENTERPRISES | H5: 156600 | I5: =ROUND(H5*18%,0) | J5: =+H5+I5 | K5: =ROUND((H5+I5)*2%,0) | L5: =H5*0.1% | M5: =H5*2.25%*118% | N5: =H5*2.25%*2% | O5: =M5-N5 | P5: =ROUND(O5+L5,0) | Q5: 0 | R5: =ROUND(H5*Q5,0) | S5: =ROUND(H5*117.65%-R5,0) | T5: =ROUND(H5*25%,0) | U5: =+T5 | V5: 13.08.2026 | W5: =ROUND(H5*92.65%-R5,0) | X5: 145090 | Y5: 24.08.2026 | Z5: =IF(OR(Y5="",Y5=0),H5*0.0118*CEILING((TODAY()-DATE(2026,8,22))/7,1),IF(DATE(VALUE(RIGHT(Y5,4)),VALUE(MID(Y5,4,2)),VALUE(LEFT(Y5,2)))<=DATE(2026,8,24),0,H5*0.0118*CEILING((DATE(VALUE(RIGHT(Y5,4)),VALUE(MID(Y5,4,2)),VALUE(LEFT(Y5,2)))-DATE(2026,8,22))/7,1))) | AC5: =U5+X5+AA5 | AD5: =S5-AC5 | AE5: DR2640100030 | AF5: 1800003302 | AG5: 27.08.2026
A6: 28 | B6: Scrap of Copper of faulty AC compressor | C6: 1456 | D6: 21977 | E6: KG | F6: 1875 | G6: F R KHANS ENTERPRISES | H6: 40768 | I6: =ROUND(H6*18%,0) | J6: =+H6+I6 | K6: =ROUND((H6+I6)*2%,0) | L6: =H6*0.1% | M6: =H6*2.25%*118% | N6: =H6*2.25%*2% | O6: =M6-N6 | P6: =ROUND(O6+L6,0) | Q6: 0 | R6: =ROUND(H6*Q6,0) | S6: =ROUND(H6*117.65%-R6,0) | T6: =ROUND(H6*25%,0) | U6: 10192 | V6: 11.08.2026 | W6: =ROUND(H6*92.65%-R6,0) | X6: =+W6+R6 | Y6: 20.08.2026 | Z6: =IF(OR(Y6="",Y6=0),H6*0.0118*CEILING((TODAY()-DATE(2026,8,22))/7,1),IF(DATE(VALUE(RIGHT(Y6,4)),VALUE(MID(Y6,4,2)),VALUE(LEFT(Y6,2)))<=DATE(2026,8,24),0,H6*0.0118*CEILING((DATE(VALUE(RIGHT(Y6,4)),VALUE(MID(Y6,4,2)),VALUE(LEFT(Y6,2)))-DATE(2026,8,22))/7,1))) | AC6: =U6+X6+AA6 | AD6: =S6-AC6 | AE6: DR2640100047 | AF6: 1800003346 | AG6: 27.08.2026
A7: 3000 | B7: Scrap of MS (extracted from equip cage and empty Sf6 gas cylinder) | C7: 66 | D7: 21977 | E7: KG | F7: 1876 | G7: F R KHANS ENTERPRISES | H7: 198000 | I7: =ROUND(H7*18%,0) | J7: =+H7+I7 | K7: =ROUND((H7+I7)*2%,0) | L7: =H7*0.1% | M7: =H7*2.25%*118% | N7: =H7*2.25%*2% | O7: =M7-N7 | P7: =ROUND(O7+L7,0) | Q7: 0 | R7: =ROUND(H7*Q7,0) | S7: =ROUND(H7*117.65%-R7,0) | T7: =ROUND(H7*25%,0) | U7: 49500 | V7: 11.08.2026 | W7: =ROUND(H7*92.65%-R7,0) | X7: =+W7+R7-1 | Y7: 20.08.2026 | Z7: =IF(OR(Y7="",Y7=0),H7*0.0118*CEILING((TODAY()-DATE(2026,8,22))/7,1),IF(DATE(VALUE(RIGHT(Y7,4)),VALUE(MID(Y7,4,2)),VALUE(LEFT(Y7,2)))<=DATE(2026,8,24),0,H7*0.0118*CEILING((DATE(VALUE(RIGHT(Y7,4)),VALUE(MID(Y7,4,2)),VALUE(LEFT(Y7,2)))-DATE(2026,8,22))/7,1))) | AC7: =U7+X7+AA7 | AD7: =S7-AC7 | AE7: DR2640100048 | AF7: 1800003347 | AG7: 27.08.2026
A8: 7253 | B8: SCRAP ACSR CONDUCTORS (Conductor Pieces) | C8: 227 | D8: 21980 | E8: KG | F8: 1923 | G8: OMKAR STEELS | H8: 1646431 | I8: =ROUND(H8*18%,0) | J8: =+H8+I8 | K8: =ROUND((H8+I8)*2%,0) | L8: =H8*0.1% | M8: =H8*2.25%*118% | N8: =H8*2.25%*2% | O8: =M8-N8 | P8: =ROUND(O8+L8,0) | Q8: 0.02 | R8: =ROUND(H8*Q8,0) | S8: =ROUND(H8*117.65%-R8,0) | T8: =ROUND(H8*25%,0) | U8: =+T8 | V8: 14.08.2026 | W8: =ROUND(H8*92.65%-R8,0) | X8: 1492490 | Y8: 24.08.2026 | Z8: =IF(OR(Y8="",Y8=0),H8*0.0118*CEILING((TODAY()-DATE(2026,8,22))/7,1),IF(DATE(VALUE(RIGHT(Y8,4)),VALUE(MID(Y8,4,2)),VALUE(LEFT(Y8,2)))<=DATE(2026,8,24),0,H8*0.0118*CEILING((DATE(VALUE(RIGHT(Y8,4)),VALUE(MID(Y8,4,2)),VALUE(LEFT(Y8,2)))-DATE(2026,8,22))/7,1))) | AC8: =U8+X8+AA8 | AD8: =S8-AC8 | AE8: DR2640100045 | AF8: 1800003315 | AG8: 27.08.2026
A9: 1 | B9: Scrap Power Transformer | C9: 2787314 | D9: 21977 | E9: NO | F9: 1976 | G9: SHAR JAHAN TRADERS | H9: 2787314 | I9: =ROUND(H9*18%,0) | J9: =+H9+I9 | K9: =ROUND((H9+I9)*2%,0) | L9: =H9*0.1% | M9: =H9*2.25%*118% | N9: =H9*2.25%*2% | O9: =M9-N9 | P9: =ROUND(O9+L9,0) | Q9: 0 | R9: =ROUND(H9*Q9,0) | S9: =ROUND(H9*117.65%-R9,0) | T9: =ROUND(H9*25%,0) | U9: =+T9 | V9: 13.08.2026 | W9: =ROUND(H9*92.65%-R9,0) | X9: 2582447.1 | Y9: 13.08.2026 | Z9: =IF(OR(Y9="",Y9=0),H9*0.0118*CEILING((TODAY()-DATE(2026,8,22))/7,1),IF(DATE(VALUE(RIGHT(Y9,4)),VALUE(MID(Y9,4,2)),VALUE(LEFT(Y9,2)))<=DATE(2026,8,24),0,H9*0.0118*CEILING((DATE(VALUE(RIGHT(Y9,4)),VALUE(MID(Y9,4,2)),VALUE(LEFT(Y9,2)))-DATE(2026,8,22))/7,1))) | AC9: =U9+X9+AA9 | AD9: =S9-AC9 | AE9: DR2640100023 | AF9: 1800003194 | AG9: 17.08.2026
A10: 4 | B10: Scrap of 132 KV CT | C10: 51511 | D10: 21977 | E10: NO | F10: 2002 | G10: NATIONAL ENTERPRISES | H10: 206044 | I10: =ROUND(H10*18%,0) | J10: =+H10+I10 | K10: =ROUND((H10+I10)*2%,0) | L10: =H10*0.1% | M10: =H10*2.25%*118% | N10: =H10*2.25%*2% | O10: =M10-N10 | P10: =ROUND(O10+L10,0) | Q10: 0 | R10: =ROUND(H10*Q10,0) | S10: =ROUND(H10*117.65%-R10,0) | T10: =ROUND(H10*25%,0) | U10: =+T10 | V10: 13.08.2026 | W10: =ROUND(H10*92.65%-R10,0) | X10: 190900 | Y10: 24.08.2026 | Z10: =IF(OR(Y10="",Y10=0),H10*0.0118*CEILING((TODAY()-DATE(2026,8,22))/7,1),IF(DATE(VALUE(RIGHT(Y10,4)),VALUE(MID(Y10,4,2)),VALUE(LEFT(Y10,2)))<=DATE(2026,8,24),0,H10*0.0118*CEILING((DATE(VALUE(RIGHT(Y10,4)),VALUE(MID(Y10,4,2)),VALUE(LEFT(Y10,2)))-DATE(2026,8,22))/7,1))) | AC10: =U10+X10+AA10 | AD10: =S10-AC10 | AE10: DR2640100031 | AF10: 1800003303 | AG10: 27.08.2026
A11: 1 | B11: Scrap of 145 KV CB | C11: 65007 | D11: 21977 | E11: NO | F11: 2003 | G11: NATIONAL ENTERPRISES | H11: 65007 | I11: =ROUND(H11*18%,0) | J11: =+H11+I11 | K11: =ROUND((H11+I11)*2%,0) | L11: =H11*0.1% | M11: =H11*2.25%*118% | N11: =H11*2.25%*2% | O11: =M11-N11 | P11: =ROUND(O11+L11,0) | Q11: 0 | R11: =ROUND(H11*Q11,0) | S11: =ROUND(H11*117.65%-R11,0) | T11: =ROUND(H11*25%,0) | U11: =+T11 | V11: 13.08.2026 | W11: =ROUND(H11*92.65%-R11,0) | X11: 60229 | Y11: 24.08.2026 | Z11: =IF(OR(Y11="",Y11=0),H11*0.0118*CEILING((TODAY()-DATE(2026,8,22))/7,1),IF(DATE(VALUE(RIGHT(Y11,4)),VALUE(MID(Y11,4,2)),VALUE(LEFT(Y11,2)))<=DATE(2026,8,24),0,H11*0.0118*CEILING((DATE(VALUE(RIGHT(Y11,4)),VALUE(MID(Y11,4,2)),VALUE(LEFT(Y11,2)))-DATE(2026,8,22))/7,1))) | AC11: =U11+X11+AA11 | AD11: =S11-AC11 | AE11: DR2640100032 | AF11: 1800003304 | AG11: 27.08.2026
A12: 1 | B12: Scrap of 220KV CT | C12: 70006 | D12: 21977 | E12: NO | F12: 2005 | G12: NATIONAL ENTERPRISES | H12: 70006 | I12: =ROUND(H12*18%,0) | J12: =+H12+I12 | K12: =ROUND((H12+I12)*2%,0) | L12: =H12*0.1% | M12: =H12*2.25%*118% | N12: =H12*2.25%*2% | O12: =M12-N12 | P12: =ROUND(O12+L12,0) | Q12: 0 | R12: =ROUND(H12*Q12,0) | S12: =ROUND(H12*117.65%-R12,0) | T12: =ROUND(H12*25%,0) | U12: =+T12 | V12: 13.08.2026 | W12: =ROUND(H12*92.65%-R12,0) | X12: 64859 | Y12: 24.08.2026 | Z12: =IF(OR(Y12="",Y12=0),H12*0.0118*CEILING((TODAY()-DATE(2026,8,22))/7,1),IF(DATE(VALUE(RIGHT(Y12,4)),VALUE(MID(Y12,4,2)),VALUE(LEFT(Y12,2)))<=DATE(2026,8,24),0,H12*0.0118*CEILING((DATE(VALUE(RIGHT(Y12,4)),VALUE(MID(Y12,4,2)),VALUE(LEFT(Y12,2)))-DATE(2026,8,22))/7,1))) | AC12: =U12+X12+AA12 | AD12: =S12-AC12 | AE12: DR2640100033 | AF12: 1800003305 | AG12: 27.08.2026
A13: 25 | B13: Scrap of empty oil drums | C13: 700 | D13: 21977 | E13: NO | F13: 2006 | G13: STERLING ENTERPRISES | H13: 17500 | I13: =ROUND(H13*18%,0) | J13: =+H13+I13 | K13: =ROUND((H13+I13)*2%,0) | L13: =H13*0.1% | M13: =H13*2.25%*118% | N13: =H13*2.25%*2% | O13: =M13-N13 | P13: =ROUND(O13+L13,0) | Q13: 0 | R13: =ROUND(H13*Q13,0) | S13: =ROUND(H13*117.65%-R13,0) | T13: =ROUND(H13*25%,0) | U13: 4375 | V13: 11.08.2026 | W13: =ROUND(H13*92.65%-R13,0) | X13: 16214 | Y13: 11.08.2026 | Z13: =IF(OR(Y13="",Y13=0),H13*0.0118*CEILING((TODAY()-DATE(2026,8,22))/7,1),IF(DATE(VALUE(RIGHT(Y13,4)),VALUE(MID(Y13,4,2)),VALUE(LEFT(Y13,2)))<=DATE(2026,8,24),0,H13*0.0118*CEILING((DATE(VALUE(RIGHT(Y13,4)),VALUE(MID(Y13,4,2)),VALUE(LEFT(Y13,2)))-DATE(2026,8,22))/7,1))) | AC13: =U13+X13+AA13 | AD13: =S13-AC13 | AE13: DR2640100018 | AF13: 1800003156 | AG13: 14.08.2026
A14: 1 | B14: SCRAP POWER TRANSFORMER | C14: 3857116 | D14: 21977 | E14: NO | F14: 2007 | G14: SHAR JAHAN TRADERS | H14: 3857116 | I14: =ROUND(H14*18%,0) | J14: =+H14+I14 | K14: =ROUND((H14+I14)*2%,0) | L14: =H14*0.1% | M14: =H14*2.25%*118% | N14: =H14*2.25%*2% | O14: =M14-N14 | P14: =ROUND(O14+L14,0) | Q14: 0 | R14: =ROUND(H14*Q14,0) | S14: =ROUND(H14*117.65%-R14,0) | T14: =ROUND(H14*25%,0) | U14: =+T14 | V14: 13.08.2026 | W14: =ROUND(H14*92.65%-R14,0) | X14: 3573618.9 | Y14: 13.08.2026 | Z14: =IF(OR(Y14="",Y14=0),H14*0.0118*CEILING((TODAY()-DATE(2026,8,22))/7,1),IF(DATE(VALUE(RIGHT(Y14,4)),VALUE(MID(Y14,4,2)),VALUE(LEFT(Y14,2)))<=DATE(2026,8,24),0,H14*0.0118*CEILING((DATE(VALUE(RIGHT(Y14,4)),VALUE(MID(Y14,4,2)),VALUE(LEFT(Y14,2)))-DATE(2026,8,22))/7,1))) | AC14: =U14+X14+AA14 | AD14: =S14-AC14 | AE14: DR2640100024 | AF14: 1800003196 | AG14: 17.08.2026
A15: 250 | B15: Scrap of empty oil Druam | C15: 543 | D15: 21977 | E15: NO | F15: 2008 | G15: HIND TRADERS | H15: 135750 | I15: =ROUND(H15*18%,0) | J15: =+H15+I15 | K15: =ROUND((H15+I15)*2%,0) | L15: =H15*0.1% | M15: =H15*2.25%*118% | N15: =H15*2.25%*2% | O15: =M15-N15 | P15: =ROUND(O15+L15,0) | Q15: 0 | R15: =ROUND(H15*Q15,0) | S15: =ROUND(H15*117.65%-R15,0) | T15: =ROUND(H15*25%,0) | U15: 33938 | V15: 14.08.2026 | W15: =ROUND(H15*92.65%-R15,0) | X15: 125772 | Y15: 18.08.2026 | Z15: =IF(OR(Y15="",Y15=0),H15*0.0118*CEILING((TODAY()-DATE(2026,8,22))/7,1),IF(DATE(VALUE(RIGHT(Y15,4)),VALUE(MID(Y15,4,2)),VALUE(LEFT(Y15,2)))<=DATE(2026,8,24),0,H15*0.0118*CEILING((DATE(VALUE(RIGHT(Y15,4)),VALUE(MID(Y15,4,2)),VALUE(LEFT(Y15,2)))-DATE(2026,8,22))/7,1))) | AC15: =U15+X15+AA15 | AD15: =S15-AC15 | AE15: DR2640100026 | AF15: 1800003247 | AG15: 20.08.2026
A16: 22 | B16: Scrap of empty oil Barrel | C16: 700 | D16: 21977 | E16: NO | F16: 2011 | G16: STERLING ENTERPRISES | H16: 15400 | I16: =ROUND(H16*18%,0) | J16: =+H16+I16 | K16: =ROUND((H16+I16)*2%,0) | L16: =H16*0.1% | M16: =H16*2.25%*118% | N16: =H16*2.25%*2% | O16: =M16-N16 | P16: =ROUND(O16+L16,0) | Q16: 0 | R16: =ROUND(H16*Q16,0) | S16: =ROUND(H16*117.65%-R16,0) | T16: =ROUND(H16*25%,0) | U16: 3850 | V16: 11.08.2026 | W16: =ROUND(H16*92.65%-R16,0) | X16: 14267 | Y16: 11.08.2026 | Z16: =IF(OR(Y16="",Y16=0),H16*0.0118*CEILING((TODAY()-DATE(2026,8,22))/7,1),IF(DATE(VALUE(RIGHT(Y16,4)),VALUE(MID(Y16,4,2)),VALUE(LEFT(Y16,2)))<=DATE(2026,8,24),0,H16*0.0118*CEILING((DATE(VALUE(RIGHT(Y16,4)),VALUE(MID(Y16,4,2)),VALUE(LEFT(Y16,2)))-DATE(2026,8,22))/7,1))) | AC16: =U16+X16+AA16 | AD16: =S16-AC16 | AE16: DR2640100019 | AF16: 1800003157 | AG16: 14.08.2026
A17: 100 | B17: Scrap of empty oil Barrels | C17: 710 | D17: 21978 | E17: NO | F17: 2015 | G17: STERLING ENTERPRISES | H17: 71000 | I17: =ROUND(H17*18%,0) | J17: =+H17+I17 | K17: =ROUND((H17+I17)*2%,0) | L17: =H17*0.1% | M17: =H17*2.25%*118% | N17: =H17*2.25%*2% | O17: =M17-N17 | P17: =ROUND(O17+L17,0) | Q17: 0 | R17: =ROUND(H17*Q17,0) | S17: =ROUND(H17*117.65%-R17,0) | T17: =ROUND(H17*25%,0) | U17: 17750 | V17: 11.08.2026 | W17: =ROUND(H17*92.65%-R17,0) | X17: =+W17 | Y17: 11.08.2026 | Z17: =IF(OR(Y17="",Y17=0),H17*0.0118*CEILING((TODAY()-DATE(2026,8,22))/7,1),IF(DATE(VALUE(RIGHT(Y17,4)),VALUE(MID(Y17,4,2)),VALUE(LEFT(Y17,2)))<=DATE(2026,8,24),0,H17*0.0118*CEILING((DATE(VALUE(RIGHT(Y17,4)),VALUE(MID(Y17,4,2)),VALUE(LEFT(Y17,2)))-DATE(2026,8,22))/7,1))) | AC17: =U17+X17+AA17 | AD17: =S17-AC17 | AE17: DR2640100020 | AF17: 1800003158 | AG17: 14.08.2026
A18: 1 | B18: Scrap of 220 KV Circuit Breaker | C18: 220001 | D18: 21978 | E18: NO | F18: 2018 | G18: NATIONAL ENTERPRISES | H18: 220001 | I18: =ROUND(H18*18%,0) | J18: =+H18+I18 | K18: =ROUND((H18+I18)*2%,0) | L18: =H18*0.1% | M18: =H18*2.25%*118% | N18: =H18*2.25%*2% | O18: =M18-N18 | P18: =ROUND(O18+L18,0) | Q18: 0 | R18: =ROUND(H18*Q18,0) | S18: =ROUND(H18*117.65%-R18,0) | T18: =ROUND(H18*25%,0) | U18: =+T18 | V18: 13.08.2026 | W18: =ROUND(H18*92.65%-R18,0) | X18: 203831 | Y18: 24.08.2026 | Z18: =IF(OR(Y18="",Y18=0),H18*0.0118*CEILING((TODAY()-DATE(2026,8,22))/7,1),IF(DATE(VALUE(RIGHT(Y18,4)),VALUE(MID(Y18,4,2)),VALUE(LEFT(Y18,2)))<=DATE(2026,8,24),0,H18*0.0118*CEILING((DATE(VALUE(RIGHT(Y18,4)),VALUE(MID(Y18,4,2)),VALUE(LEFT(Y18,2)))-DATE(2026,8,22))/7,1))) | AC18: =U18+X18+AA18 | AD18: =S18-AC18 | AE18: DR2640100034 | AF18: 1800003306 | AG18: 27.08.2026
A19: 1 | B19: Scrap of 220 KV Circuit Breaker | C19: 210001 | D19: 21978 | E19: NO | F19: 2019 | G19: NATIONAL ENTERPRISES | H19: 210001 | I19: =ROUND(H19*18%,0) | J19: =+H19+I19 | K19: =ROUND((H19+I19)*2%,0) | L19: =H19*0.1% | M19: =H19*2.25%*118% | N19: =H19*2.25%*2% | O19: =M19-N19 | P19: =ROUND(O19+L19,0) | Q19: 0 | R19: =ROUND(H19*Q19,0) | S19: =ROUND(H19*117.65%-R19,0) | T19: =ROUND(H19*25%,0) | U19: =+T19 | V19: 13.08.2026 | W19: =ROUND(H19*92.65%-R19,0) | X19: 194566 | Y19: 24.08.2026 | Z19: =IF(OR(Y19="",Y19=0),H19*0.0118*CEILING((TODAY()-DATE(2026,8,22))/7,1),IF(DATE(VALUE(RIGHT(Y19,4)),VALUE(MID(Y19,4,2)),VALUE(LEFT(Y19,2)))<=DATE(2026,8,24),0,H19*0.0118*CEILING((DATE(VALUE(RIGHT(Y19,4)),VALUE(MID(Y19,4,2)),VALUE(LEFT(Y19,2)))-DATE(2026,8,22))/7,1))) | AC19: =U19+X19+AA19 | AD19: =S19-AC19 | AE19: DR2640100035 | AF19: 1800003307 | AG19: 27.08.2026
A20: 3500 | B20: SCRAP 80MM² AAAC EARTHWIRE | C20: 333 | D20: 21978 | E20: KG | F20: 2020 | G20: OMKAR STEELS | H20: 1165500 | I20: =ROUND(H20*18%,0) | J20: =+H20+I20 | K20: =ROUND((H20+I20)*2%,0) | L20: =H20*0.1% | M20: =H20*2.25%*118% | N20: =H20*2.25%*2% | O20: =M20-N20 | P20: =ROUND(O20+L20,0) | Q20: 0.02 | R20: =ROUND(H20*Q20,0) | S20: =ROUND(H20*117.65%-R20,0) | T20: =ROUND(H20*25%,0) | U20: 291375 | V20: 10.08.2026 | W20: =ROUND(H20*92.65%-R20,0) | X20: 1056525 | Y20: 10.08.2026 | Z20: =IF(OR(Y20="",Y20=0),H20*0.0118*CEILING((TODAY()-DATE(2026,8,22))/7,1),IF(DATE(VALUE(RIGHT(Y20,4)),VALUE(MID(Y20,4,2)),VALUE(LEFT(Y20,2)))<=DATE(2026,8,24),0,H20*0.0118*CEILING((DATE(VALUE(RIGHT(Y20,4)),VALUE(MID(Y20,4,2)),VALUE(LEFT(Y20,2)))-DATE(2026,8,22))/7,1))) | AC20: =U20+X20+AA20 | AD20: =S20-AC20 | AE20: DR2640100017 | AF20: 1800003065 | AG20: 12.08.2026
A21: 3 | B21: Scrap of 132 KV CT | C21: 110200 | D21: 21978 | E21: NO | F21: 2022 | G21: NATIONAL SCRAP AND BUILDING MATERIAL SUPPLIER | H21: 330600 | I21: =ROUND(H21*18%,0) | J21: =+H21+I21 | K21: =ROUND((H21+I21)*2%,0) | L21: =H21*0.1% | M21: =H21*2.25%*118% | N21: =H21*2.25%*2% | O21: =M21-N21 | P21: =ROUND(O21+L21,0) | Q21: 0 | R21: =ROUND(H21*Q21,0) | S21: =ROUND(H21*117.65%-R21,0) | T21: =ROUND(H21*25%,0) | U21: =+T21 | V21: 14.08.2026 | W21: =ROUND(H21*92.65%-R21,0) | X21: 306301 | Y21: 21.08.2026 | Z21: =IF(OR(Y21="",Y21=0),H21*0.0118*CEILING((TODAY()-DATE(2026,8,22))/7,1),IF(DATE(VALUE(RIGHT(Y21,4)),VALUE(MID(Y21,4,2)),VALUE(LEFT(Y21,2)))<=DATE(2026,8,24),0,H21*0.0118*CEILING((DATE(VALUE(RIGHT(Y21,4)),VALUE(MID(Y21,4,2)),VALUE(LEFT(Y21,2)))-DATE(2026,8,22))/7,1))) | AC21: =U21+X21+AA21 | AD21: =S21-AC21 | AE21: DR2640100028 | AF21: 1800003269 | AG21: 24.08.2026
A22: 3 | B22: Scrap of 132 KV CT | C22: 83743 | D22: 21978 | E22: NO | F22: 2023 | G22: NATIONAL ENTERPRISES | H22: 251229 | I22: =ROUND(H22*18%,0) | J22: =+H22+I22 | K22: =ROUND((H22+I22)*2%,0) | L22: =H22*0.1% | M22: =H22*2.25%*118% | N22: =H22*2.25%*2% | O22: =M22-N22 | P22: =ROUND(O22+L22,0) | Q22: 0 | R22: =ROUND(H22*Q22,0) | S22: =ROUND(H22*117.65%-R22,0) | T22: =ROUND(H22*25%,0) | U22: =+T22 | V22: 13.08.2026 | W22: =ROUND(H22*92.65%-R22,0) | X22: 232764 | Y22: 24.08.2026 | Z22: =IF(OR(Y22="",Y22=0),H22*0.0118*CEILING((TODAY()-DATE(2026,8,22))/7,1),IF(DATE(VALUE(RIGHT(Y22,4)),VALUE(MID(Y22,4,2)),VALUE(LEFT(Y22,2)))<=DATE(2026,8,24),0,H22*0.0118*CEILING((DATE(VALUE(RIGHT(Y22,4)),VALUE(MID(Y22,4,2)),VALUE(LEFT(Y22,2)))-DATE(2026,8,22))/7,1))) | AC22: =U22+X22+AA22 | AD22: =S22-AC22 | AE22: DR2640100044 | AF22: 1800003308 | AG22: 27.08.2026
A23: 90 | B23: Scrap of empty oil Barrels | C23: 700 | D23: 21978 | E23: NO | F23: 2025 | G23: STERLING ENTERPRISES | H23: 63000 | I23: =ROUND(H23*18%,0) | J23: =+H23+I23 | K23: =ROUND((H23+I23)*2%,0) | L23: =H23*0.1% | M23: =H23*2.25%*118% | N23: =H23*2.25%*2% | O23: =M23-N23 | P23: =ROUND(O23+L23,0) | Q23: 0 | R23: =ROUND(H23*Q23,0) | S23: =ROUND(H23*117.65%-R23,0) | T23: =ROUND(H23*25%,0) | U23: 15750 | V23: 11.08.2026 | W23: =ROUND(H23*92.65%-R23,0) | X23: 58418 | Y23: 11.08.2026 | Z23: =IF(OR(Y23="",Y23=0),H23*0.0118*CEILING((TODAY()-DATE(2026,8,22))/7,1),IF(DATE(VALUE(RIGHT(Y23,4)),VALUE(MID(Y23,4,2)),VALUE(LEFT(Y23,2)))<=DATE(2026,8,24),0,H23*0.0118*CEILING((DATE(VALUE(RIGHT(Y23,4)),VALUE(MID(Y23,4,2)),VALUE(LEFT(Y23,2)))-DATE(2026,8,22))/7,1))) | AC23: =U23+X23+AA23 | AD23: =S23-AC23 | AE23: DR2640100021 | AF23: 1800003160 | AG23: 14.08.2026
A24: 1 | B24: Scrap of 132 KV CT | C24: 50003 | D24: 21978 | E24: NO | F24: 2027 | G24: NATIONAL ENTERPRISES | H24: 50003 | I24: =ROUND(H24*18%,0) | J24: =+H24+I24 | K24: =ROUND((H24+I24)*2%,0) | L24: =H24*0.1% | M24: =H24*2.25%*118% | N24: =H24*2.25%*2% | O24: =M24-N24 | P24: =ROUND(O24+L24,0) | Q24: 0 | R24: =ROUND(H24*Q24,0) | S24: =ROUND(H24*117.65%-R24,0) | T24: =ROUND(H24*25%,0) | U24: =+T24 | V24: 13.08.2026 | W24: =ROUND(H24*92.65%-R24,0) | X24: 46328 | Y24: 24.08.2026 | Z24: =IF(OR(Y24="",Y24=0),H24*0.0118*CEILING((TODAY()-DATE(2026,8,22))/7,1),IF(DATE(VALUE(RIGHT(Y24,4)),VALUE(MID(Y24,4,2)),VALUE(LEFT(Y24,2)))<=DATE(2026,8,24),0,H24*0.0118*CEILING((DATE(VALUE(RIGHT(Y24,4)),VALUE(MID(Y24,4,2)),VALUE(LEFT(Y24,2)))-DATE(2026,8,22))/7,1))) | AC24: =U24+X24+AA24 | AD24: =S24-AC24 | AE24: DR2640100036 | AF24: 1800003309 | AG24: 27.08.2026
A25: 1000 | B25: Scrap Empty Oil Drum/ Barrel | C25: 517 | D25: 21978 | E25: NO | F25: 2033 | G25: WATAN SCRAP TRADERS | H25: 517000 | I25: =ROUND(H25*18%,0) | J25: =+H25+I25 | K25: =ROUND((H25+I25)*2%,0) | L25: =H25*0.1% | M25: =H25*2.25%*118% | N25: =H25*2.25%*2% | O25: =M25-N25 | P25: =ROUND(O25+L25,0) | Q25: 0 | R25: =ROUND(H25*Q25,0) | S25: =ROUND(H25*117.65%-R25,0) | T25: =ROUND(H25*25%,0) | U25: 129250 | V25: 14.08.2026 | W25: =ROUND(H25*92.65%-R25,0) | X25: 479001 | Y25: 21.08.2026 | Z25: =IF(OR(Y25="",Y25=0),H25*0.0118*CEILING((TODAY()-DATE(2026,8,22))/7,1),IF(DATE(VALUE(RIGHT(Y25,4)),VALUE(MID(Y25,4,2)),VALUE(LEFT(Y25,2)))<=DATE(2026,8,24),0,H25*0.0118*CEILING((DATE(VALUE(RIGHT(Y25,4)),VALUE(MID(Y25,4,2)),VALUE(LEFT(Y25,2)))-DATE(2026,8,22))/7,1))) | AC25: =U25+X25+AA25 | AD25: =S25-AC25 | AE25: DR2640100042 | AF25: 1800003317 | AG25: 27.08.2026
A26: 2 | B26: Scrap of 132 KV Wave Trap | C26: 14001 | D26: 21978 | E26: NO | F26: 2035 | G26: NATIONAL ENTERPRISES | H26: 28002 | I26: =ROUND(H26*18%,0) | J26: =+H26+I26 | K26: =ROUND((H26+I26)*2%,0) | L26: =H26*0.1% | M26: =H26*2.25%*118% | N26: =H26*2.25%*2% | O26: =M26-N26 | P26: =ROUND(O26+L26,0) | Q26: 0 | R26: =ROUND(H26*Q26,0) | S26: =ROUND(H26*117.65%-R26,0) | T26: =ROUND(H26*25%,0) | U26: =+T26 | V26: 13.08.2026 | W26: =ROUND(H26*92.65%-R26,0) | X26: 25943 | Y26: 24.08.2026 | Z26: =IF(OR(Y26="",Y26=0),H26*0.0118*CEILING((TODAY()-DATE(2026,8,22))/7,1),IF(DATE(VALUE(RIGHT(Y26,4)),VALUE(MID(Y26,4,2)),VALUE(LEFT(Y26,2)))<=DATE(2026,8,24),0,H26*0.0118*CEILING((DATE(VALUE(RIGHT(Y26,4)),VALUE(MID(Y26,4,2)),VALUE(LEFT(Y26,2)))-DATE(2026,8,22))/7,1))) | AC26: =U26+X26+AA26 | AD26: =S26-AC26 | AE26: DR2640100037 | AF26: 1800003310 | AG26: 27.08.2026
A27: 8.2 | B27: Mix Scrap (Tower angles & 0.2 ACSR Condutor pieces) | C27: 67000 | D27: 21978 | E27: MT | F27: 2036 | G27: M I SCRAP TRADERS | H27: 549400 | I27: =ROUND(H27*18%,0) | J27: =+H27+I27 | K27: =ROUND((H27+I27)*2%,0) | L27: =H27*0.1% | M27: =H27*2.25%*118% | N27: =H27*2.25%*2% | O27: =M27-N27 | P27: =ROUND(O27+L27,0) | Q27: 0.02 | R27: =ROUND(H27*Q27,0) | S27: =ROUND(H27*117.65%-R27,0) | T27: =ROUND(H27*25%,0) | U27: 137350 | V27: 14.08.2026 | W27: =ROUND(H27*92.65%-R27,0) | Y27: 0 | Z27: =IF(OR(Y27="",Y27=0),H27*0.0118*CEILING((TODAY()-DATE(2026,8,22))/7,1),IF(DATE(VALUE(RIGHT(Y27,4)),VALUE(MID(Y27,4,2)),VALUE(LEFT(Y27,2)))<=DATE(2026,8,24),0,H27*0.0118*CEILING((DATE(VALUE(RIGHT(Y27,4)),VALUE(MID(Y27,4,2)),VALUE(LEFT(Y27,2)))-DATE(2026,8,22))/7,1))) | AC27: =U27+X27+AA27 | AD27: =S27-AC27
A28: 50 | B28: Scrap of empty oil Barrels | C28: 531 | D28: 21978 | E28: NO | F28: 2037 | G28: WATAN SCRAP TRADERS | H28: 26550 | I28: =ROUND(H28*18%,0) | J28: =+H28+I28 | K28: =ROUND((H28+I28)*2%,0) | L28: =H28*0.1% | M28: =H28*2.25%*118% | N28: =H28*2.25%*2% | O28: =M28-N28 | P28: =ROUND(O28+L28,0) | Q28: 0 | R28: =ROUND(H28*Q28,0) | S28: =ROUND(H28*117.65%-R28,0) | T28: =ROUND(H28*25%,0) | U28: 6638 | V28: 14.08.2026 | W28: =ROUND(H28*92.65%-R28,0) | X28: 24598 | Y28: 21.08.2026 | Z28: =IF(OR(Y28="",Y28=0),H28*0.0118*CEILING((TODAY()-DATE(2026,8,22))/7,1),IF(DATE(VALUE(RIGHT(Y28,4)),VALUE(MID(Y28,4,2)),VALUE(LEFT(Y28,2)))<=DATE(2026,8,24),0,H28*0.0118*CEILING((DATE(VALUE(RIGHT(Y28,4)),VALUE(MID(Y28,4,2)),VALUE(LEFT(Y28,2)))-DATE(2026,8,22))/7,1))) | AC28: =U28+X28+AA28 | AD28: =S28-AC28 | AE28: DR2640100043 | AF28: 1800003318 | AG28: 27.08.2026
A29: 3 | B29: Scrap of 33 KV CT | C29: 90002 | D29: 21978 | E29: NO | F29: 2040 | G29: STERLING ENTERPRISES | H29: 270006 | I29: =ROUND(H29*18%,0) | J29: =+H29+I29 | K29: =ROUND((H29+I29)*2%,0) | L29: =H29*0.1% | M29: =H29*2.25%*118% | N29: =H29*2.25%*2% | O29: =M29-N29 | P29: =ROUND(O29+L29,0) | Q29: 0 | R29: =ROUND(H29*Q29,0) | S29: =ROUND(H29*117.65%-R29,0) | T29: =ROUND(H29*25%,0) | U29: 67502 | V29: 11.08.2026 | W29: =ROUND(H29*92.65%-R29,0) | Y29: 0 | Z29: =IF(OR(Y29="",Y29=0),H29*0.0118*CEILING((TODAY()-DATE(2026,8,22))/7,1),IF(DATE(VALUE(RIGHT(Y29,4)),VALUE(MID(Y29,4,2)),VALUE(LEFT(Y29,2)))<=DATE(2026,8,24),0,H29*0.0118*CEILING((DATE(VALUE(RIGHT(Y29,4)),VALUE(MID(Y29,4,2)),VALUE(LEFT(Y29,2)))-DATE(2026,8,22))/7,1))) | AC29: =U29+X29+AA29 | AD29: =S29-AC29
A30: 5 | B30: Scrap of 132 KV CT | C30: 80000 | D30: 21979 | E30: NO | F30: 2043 | G30: NATIONAL ENTERPRISES | H30: 400000 | I30: =ROUND(H30*18%,0) | J30: =+H30+I30 | K30: =ROUND((H30+I30)*2%,0) | L30: =H30*0.1% | M30: =H30*2.25%*118% | N30: =H30*2.25%*2% | O30: =M30-N30 | P30: =ROUND(O30+L30,0) | Q30: 0 | R30: =ROUND(H30*Q30,0) | S30: =ROUND(H30*117.65%-R30,0) | T30: =ROUND(H30*25%,0) | U30: =+T30 | V30: 13.08.2026 | W30: =ROUND(H30*92.65%-R30,0) | X30: 370600 | Y30: 24.08.2026 | Z30: =IF(OR(Y30="",Y30=0),H30*0.0118*CEILING((TODAY()-DATE(2026,8,22))/7,1),IF(DATE(VALUE(RIGHT(Y30,4)),VALUE(MID(Y30,4,2)),VALUE(LEFT(Y30,2)))<=DATE(2026,8,24),0,H30*0.0118*CEILING((DATE(VALUE(RIGHT(Y30,4)),VALUE(MID(Y30,4,2)),VALUE(LEFT(Y30,2)))-DATE(2026,8,22))/7,1))) | AC30: =U30+X30+AA30 | AD30: =S30-AC30 | AE30: DR2640100038 | AF30: 1800003311 | AG30: 27.08.2026
A31: 670 | B31: Scrap of AAAC Earth wire | C31: 309 | D31: 21979 | E31: KG | F31: 2046 | G31: SAHARA ENTERPRISES | H31: 207030 | I31: =ROUND(H31*18%,0) | J31: =+H31+I31 | K31: =ROUND((H31+I31)*2%,0) | L31: =H31*0.1% | M31: =H31*2.25%*118% | N31: =H31*2.25%*2% | O31: =M31-N31 | P31: =ROUND(O31+L31,0) | Q31: 0 | R31: =ROUND(H31*Q31,0) | S31: =ROUND(H31*117.65%-R31,0) | T31: =ROUND(H31*25%,0) | U31: 51758 | V31: 11.08.2026 | W31: =ROUND(H31*92.65%-R31,0) | X31: 191812 | Y31: 21.08.2026 | Z31: =IF(OR(Y31="",Y31=0),H31*0.0118*CEILING((TODAY()-DATE(2026,8,22))/7,1),IF(DATE(VALUE(RIGHT(Y31,4)),VALUE(MID(Y31,4,2)),VALUE(LEFT(Y31,2)))<=DATE(2026,8,24),0,H31*0.0118*CEILING((DATE(VALUE(RIGHT(Y31,4)),VALUE(MID(Y31,4,2)),VALUE(LEFT(Y31,2)))-DATE(2026,8,22))/7,1))) | AC31: =U31+X31+AA31 | AD31: =S31-AC31 | AE31: DR2640100041 | AF31: 1800003316 | AG31: 27.08.2026
A32: 2 | B32: Scrap of 220 KV CT | C32: 80006 | D32: 21979 | E32: NO | F32: 2055 | G32: NATIONAL ENTERPRISES | H32: 160012 | I32: =ROUND(H32*18%,0) | J32: =+H32+I32 | K32: =ROUND((H32+I32)*2%,0) | L32: =H32*0.1% | M32: =H32*2.25%*118% | N32: =H32*2.25%*2% | O32: =M32-N32 | P32: =ROUND(O32+L32,0) | Q32: 0 | R32: =ROUND(H32*Q32,0) | S32: =ROUND(H32*117.65%-R32,0) | T32: =ROUND(H32*25%,0) | U32: =+T32 | V32: 13.08.2026 | W32: =ROUND(H32*92.65%-R32,0) | X32: 148251 | Y32: 24.08.2026 | Z32: =IF(OR(Y32="",Y32=0),H32*0.0118*CEILING((TODAY()-DATE(2026,8,22))/7,1),IF(DATE(VALUE(RIGHT(Y32,4)),VALUE(MID(Y32,4,2)),VALUE(LEFT(Y32,2)))<=DATE(2026,8,24),0,H32*0.0118*CEILING((DATE(VALUE(RIGHT(Y32,4)),VALUE(MID(Y32,4,2)),VALUE(LEFT(Y32,2)))-DATE(2026,8,22))/7,1))) | AC32: =U32+X32+AA32 | AD32: =S32-AC32 | AE32: DR2640100039 | AF32: 1800003312 | AG32: 27.08.2026
A33: 1 | B33: Scrap of 33 KV GCB | C33: 29502 | D33: 21979 | E33: NO | F33: 2059 | G33: NATIONAL ENTERPRISES | H33: 29502 | I33: =ROUND(H33*18%,0) | J33: =+H33+I33 | K33: =ROUND((H33+I33)*2%,0) | L33: =H33*0.1% | M33: =H33*2.25%*118% | N33: =H33*2.25%*2% | O33: =M33-N33 | P33: =ROUND(O33+L33,0) | Q33: 0 | R33: =ROUND(H33*Q33,0) | S33: =ROUND(H33*117.65%-R33,0) | T33: =ROUND(H33*25%,0) | U33: =+T33 | V33: 13.08.2026 | W33: =ROUND(H33*92.65%-R33,0) | X33: 27332 | Y33: 24.08.2026 | Z33: =IF(OR(Y33="",Y33=0),H33*0.0118*CEILING((TODAY()-DATE(2026,8,22))/7,1),IF(DATE(VALUE(RIGHT(Y33,4)),VALUE(MID(Y33,4,2)),VALUE(LEFT(Y33,2)))<=DATE(2026,8,24),0,H33*0.0118*CEILING((DATE(VALUE(RIGHT(Y33,4)),VALUE(MID(Y33,4,2)),VALUE(LEFT(Y33,2)))-DATE(2026,8,22))/7,1))) | AC33: =U33+X33+AA33 | AD33: =S33-AC33 | AE33: DR2640100046 | AF33: 1800003313 | AG33: 27.08.2026
A34: 30 | B34: Scrap of Empty oil Barrels | C34: 702 | D34: 21979 | E34: NO | F34: 2062 | G34: STERLING ENTERPRISES | H34: 21060 | I34: =ROUND(H34*18%,0) | J34: =+H34+I34 | K34: =ROUND((H34+I34)*2%,0) | L34: =H34*0.1% | M34: =H34*2.25%*118% | N34: =H34*2.25%*2% | O34: =M34-N34 | P34: =ROUND(O34+L34,0) | Q34: 0 | R34: =ROUND(H34*Q34,0) | S34: =ROUND(H34*117.65%-R34,0) | T34: =ROUND(H34*25%,0) | U34: 5265 | V34: 11.08.2026 | W34: =ROUND(H34*92.65%-R34,0) | X34: 19512 | Y34: 11.08.2026 | Z34: =IF(OR(Y34="",Y34=0),H34*0.0118*CEILING((TODAY()-DATE(2026,8,22))/7,1),IF(DATE(VALUE(RIGHT(Y34,4)),VALUE(MID(Y34,4,2)),VALUE(LEFT(Y34,2)))<=DATE(2026,8,24),0,H34*0.0118*CEILING((DATE(VALUE(RIGHT(Y34,4)),VALUE(MID(Y34,4,2)),VALUE(LEFT(Y34,2)))-DATE(2026,8,22))/7,1))) | AC34: =U34+X34+AA34 | AD34: =S34-AC34 | AE34: DR2640100022 | AF34: 1800003161 | AG34: 14.08.2026
A35: 150 | B35: Scrap of empty oil drums | C35: 571 | D35: 21980 | E35: NO | F35: 2067 | G35: WATAN SCRAP TRADERS | H35: 85650 | I35: =ROUND(H35*18%,0) | J35: =+H35+I35 | K35: =ROUND((H35+I35)*2%,0) | L35: =H35*0.1% | M35: =H35*2.25%*118% | N35: =H35*2.25%*2% | O35: =M35-N35 | P35: =ROUND(O35+L35,0) | Q35: 0 | R35: =ROUND(H35*Q35,0) | S35: =ROUND(H35*117.65%-R35,0) | T35: =ROUND(H35*25%,0) | U35: 21413 | V35: 14.08.2026 | W35: =ROUND(H35*92.65%-R35,0) | X35: 79354 | Y35: 20.08.2026 | Z35: =IF(OR(Y35="",Y35=0),H35*0.0118*CEILING((TODAY()-DATE(2026,8,22))/7,1),IF(DATE(VALUE(RIGHT(Y35,4)),VALUE(MID(Y35,4,2)),VALUE(LEFT(Y35,2)))<=DATE(2026,8,24),0,H35*0.0118*CEILING((DATE(VALUE(RIGHT(Y35,4)),VALUE(MID(Y35,4,2)),VALUE(LEFT(Y35,2)))-DATE(2026,8,22))/7,1))) | AC35: =U35+X35+AA35 | AD35: =S35-AC35 | AE35: DR2640100027 | AF35: 1800003248 | AG35: 20.08.2026
A36: 1 | B36: Scrap of 33 KV CB | C36: 54000 | D36: 21980 | E36: NO | F36: 2069 | G36: STERLING ENTERPRISES | H36: 54000 | I36: =ROUND(H36*18%,0) | J36: =+H36+I36 | K36: =ROUND((H36+I36)*2%,0) | L36: =H36*0.1% | M36: =H36*2.25%*118% | N36: =H36*2.25%*2% | O36: =M36-N36 | P36: =ROUND(O36+L36,0) | Q36: 0 | R36: =ROUND(H36*Q36,0) | S36: =ROUND(H36*117.65%-R36,0) | T36: =ROUND(H36*25%,0) | U36: 13500 | V36: 11.08.2026 | W36: =ROUND(H36*92.65%-R36,0) | Y36: 0 | Z36: =IF(OR(Y36="",Y36=0),H36*0.0118*CEILING((TODAY()-DATE(2026,8,22))/7,1),IF(DATE(VALUE(RIGHT(Y36,4)),VALUE(MID(Y36,4,2)),VALUE(LEFT(Y36,2)))<=DATE(2026,8,24),0,H36*0.0118*CEILING((DATE(VALUE(RIGHT(Y36,4)),VALUE(MID(Y36,4,2)),VALUE(LEFT(Y36,2)))-DATE(2026,8,22))/7,1))) | AC36: =U36+X36+AA36 | AD36: =S36-AC36
A37: 3 | B37: Scrap of 66 KV Isolater | C37: 25001 | D37: 21980 | E37: NO | F37: 2071 | G37: NATIONAL ENTERPRISES | H37: 75003 | I37: =ROUND(H37*18%,0) | J37: =+H37+I37 | K37: =ROUND((H37+I37)*2%,0) | L37: =H37*0.1% | M37: =H37*2.25%*118% | N37: =H37*2.25%*2% | O37: =M37-N37 | P37: =ROUND(O37+L37,0) | Q37: 0 | R37: =ROUND(H37*Q37,0) | S37: =ROUND(H37*117.65%-R37,0) | T37: =ROUND(H37*25%,0) | U37: =+T37 | V37: 13.08.2026 | W37: =ROUND(H37*92.65%-R37,0) | X37: 69491 | Y37: 24.08.2026 | Z37: =IF(OR(Y37="",Y37=0),H37*0.0118*CEILING((TODAY()-DATE(2026,8,22))/7,1),IF(DATE(VALUE(RIGHT(Y37,4)),VALUE(MID(Y37,4,2)),VALUE(LEFT(Y37,2)))<=DATE(2026,8,24),0,H37*0.0118*CEILING((DATE(VALUE(RIGHT(Y37,4)),VALUE(MID(Y37,4,2)),VALUE(LEFT(Y37,2)))-DATE(2026,8,22))/7,1))) | AC37: =U37+X37+AA37 | AD37: =S37-AC37 | AE37: DR2640100040 | AF37: 1800003314 | AG37: 27.08.2026
A38: 3 | B38: Scrap of 132 KV CT | C38: 70001 | D38: 21980 | E38: NO | F38: 2086 | G38: KASHYAP TRADING CO | H38: 210003 | I38: =ROUND(H38*18%,0) | J38: =+H38+I38 | K38: =ROUND((H38+I38)*2%,0) | L38: =H38*0.1% | M38: =H38*2.25%*118% | N38: =H38*2.25%*2% | O38: =M38-N38 | P38: =ROUND(O38+L38,0) | Q38: 0 | R38: =ROUND(H38*Q38,0) | S38: =ROUND(H38*117.65%-R38,0) | T38: =ROUND(H38*25%,0) | U38: 52501 | V38: 17.08.2026 | W38: =ROUND(H38*92.65%-R38,0) | X38: 194568 | Y38: 17.08.2026 | Z38: =IF(OR(Y38="",Y38=0),H38*0.0118*CEILING((TODAY()-DATE(2026,8,22))/7,1),IF(DATE(VALUE(RIGHT(Y38,4)),VALUE(MID(Y38,4,2)),VALUE(LEFT(Y38,2)))<=DATE(2026,8,24),0,H38*0.0118*CEILING((DATE(VALUE(RIGHT(Y38,4)),VALUE(MID(Y38,4,2)),VALUE(LEFT(Y38,2)))-DATE(2026,8,22))/7,1))) | AC38: =U38+X38+AA38 | AD38: =S38-AC38 | AE38: DR2640100025 | AF38: 1800003226 | AG38: 19.08.2026
A39: 2 | B39: Scrap of 66 kv TBC C & R Panel | C39: 15006 | D39: 21980 | E39: NO | F39: 2089 | G39: S M ENTERPRISES | H39: 30012 | I39: =ROUND(H39*18%,0) | J39: =+H39+I39 | K39: =ROUND((H39+I39)*2%,0) | L39: =H39*0.1% | M39: =H39*2.25%*118% | N39: =H39*2.25%*2% | O39: =M39-N39 | P39: =ROUND(O39+L39,0) | Q39: 0 | R39: =ROUND(H39*Q39,0) | S39: =ROUND(H39*117.65%-R39,0) | T39: =ROUND(H39*25%,0) | U39: 7503 | V39: 14.08.2026 | W39: =ROUND(H39*92.65%-R39,0) | X39: 27806 | Y39: 01.09.2026 | Z39: =IF(OR(Y39="",Y39=0),H39*0.0118*CEILING((TODAY()-DATE(2026,8,22))/7,1),IF(DATE(VALUE(RIGHT(Y39,4)),VALUE(MID(Y39,4,2)),VALUE(LEFT(Y39,2)))<=DATE(2026,8,24),0,H39*0.0118*CEILING((DATE(VALUE(RIGHT(Y39,4)),VALUE(MID(Y39,4,2)),VALUE(LEFT(Y39,2)))-DATE(2026,8,22))/7,1))) | AA39: 708 | AB39: 01.09.2026 | AC39: =U39+X39+AA39 | AD39: =S39-AC39
A40: 3 | B40: Scrap of 132 KV CT | C40: 40003 | D40: 21980 | E40: NO | F40: 2091 | G40: S M ENTERPRISES | H40: 120009 | I40: =ROUND(H40*18%,0) | J40: =+H40+I40 | K40: =ROUND((H40+I40)*2%,0) | L40: =H40*0.1% | M40: =H40*2.25%*118% | N40: =H40*2.25%*2% | O40: =M40-N40 | P40: =ROUND(O40+L40,0) | Q40: 0 | R40: =ROUND(H40*Q40,0) | S40: =ROUND(H40*117.65%-R40,0) | T40: =ROUND(H40*25%,0) | U40: 30002 | V40: 14.08.2026 | W40: =ROUND(H40*92.65%-R40,0) | X40: 111189 | Y40: 01.09.2026 | Z40: =IF(OR(Y40="",Y40=0),H40*0.0118*CEILING((TODAY()-DATE(2026,8,22))/7,1),IF(DATE(VALUE(RIGHT(Y40,4)),VALUE(MID(Y40,4,2)),VALUE(LEFT(Y40,2)))<=DATE(2026,8,24),0,H40*0.0118*CEILING((DATE(VALUE(RIGHT(Y40,4)),VALUE(MID(Y40,4,2)),VALUE(LEFT(Y40,2)))-DATE(2026,8,22))/7,1))) | AA40: 2832 | AB40: 01.09.2026 | AC40: =U40+X40+AA40 | AD40: =S40-AC40
H41: =SUM(H4:H40) | I41: =SUM(I4:I40) | J41: =SUM(J4:J40) | K41: =SUM(K4:K40) | L41: =SUM(L4:L40) | M41: =SUM(M4:M40) | N41: =SUM(N4:N40) | O41: =SUM(O4:O40) | P41: =SUM(P4:P40) | R41: =SUM(R4:R40) | S41: =SUM(S4:S40) | T41: =SUM(T4:T40) | U41: =SUM(U4:U40) | W41: =SUM(W4:W40) | X41: =SUM(X4:X40) | Z41: =SUM(Z4:Z40) | AA41: =SUM(AA4:AA40) | AC41: =SUM(AC4:AC40) | AD41: =SUM(AD4:AD40)
...

Sheet Collapsible - Lots Across
A1: MSTC LIMITED • BUYER × LOT COLLAPSIBLE VIEW (fields ↓ rows | lots → columns)
A2: Auctions 21977 • 21978 • 21979 • 21980 — every figure below is a live link to 'Final Calculation Sheet'
A3: HOW TO USE ▶ the − / + buttons in the grey margin on the LEFT fold a whole buyer (outer level) or a single section such as FINANCIALS (inner level) • the − / + above column O folds all lot columns away and keeps only the buyer totals • the 1 2 3 buttons at the top left expand everything again • a colour coded buyer index with totals and jump links sits at the bottom of this sheet
A5: FIELD ▸ BUYER | LOT → | B5: LOT 1 | C5: LOT 2 | D5: LOT 3 | E5: LOT 4 | F5: LOT 5 | G5: LOT 6 | H5: LOT 7 | I5: LOT 8 | J5: LOT 9 | K5: LOT 10 | L5: LOT 11 | M5: LOT 12 | N5: LOT 13 | O5: BUYER TOTAL
A6: ="▼ AL HAMD TRADE CORPORATION • "&COUNTIF('Final Calculation Sheet'!$G$4:$G$1000,"AL HAMD TRADE CORPORATION")&" LOT(S) • MAT. VALUE ₹"&TEXT(SUMIF('Final Calculation Sheet'!$G$4:$G$1000,"AL HAMD TRADE CORPORATION",'Final Calculation Sheet'!$H$4:$H$1000),"#,##0")&" • RECEIVED ₹"&TEXT(SUMIF('Final Calculation Sheet'!$G$4:$G$1000,"AL HAMD TRADE CORPORATION",'Final Calculation Sheet'!$AC$4:$AC$1000),"#,##0")&" • OUTSTANDING ₹"&TEXT(SUMIF('Final Calculation Sheet'!$G$4:$G$1000,"AL HAMD TRADE CORPORATION",'Final Calculation Sheet'!$AD$4:$AD$1000),"#,##0")
A7: Lot No. → | B7: =IF('Final Calculation Sheet'!$F$4="","",'Final Calculation Sheet'!$F$4) | O7: TOTAL
A8: ▸ LOT INFORMATION
A9: Lot No. | B9: =IF('Final Calculation Sheet'!$F$4="","",'Final Calculation Sheet'!$F$4) | O9: –
A10: Lot Name | B10: =IF('Final Calculation Sheet'!$B$4="","",'Final Calculation Sheet'!$B$4) | O10: –
A11: Bid Sheet / Auction | B11: =IF('Final Calculation Sheet'!$D$4="","",'Final Calculation Sheet'!$D$4) | O11: –
A12: Quantity | B12: =IF('Final Calculation Sheet'!$A$4="","",'Final Calculation Sheet'!$A$4) | O12: =SUM(B12:N12)
A13: Unit | B13: =IF('Final Calculation Sheet'!$E$4="","",'Final Calculation Sheet'!$E$4) | O13: –
A14: Rate (₹) | B14: =IF('Final Calculation Sheet'!$C$4="","",'Final Calculation Sheet'!$C$4) | O14: –
A15: ▸ FINANCIALS
A16: Mat. Value (₹) | B16: =IF('Final Calculation Sheet'!$H$4="","",'Final Calculation Sheet'!$H$4) | O16: =SUM(B16:N16)
A17: GST @ 18% (₹) | B17: =IF('Final Calculation Sheet'!$I$4="","",'Final Calculation Sheet'!$I$4) | O17: =SUM(B17:N17)
A18: Mat. Value + GST (₹) | B18: =IF('Final Calculation Sheet'!$J$4="","",'Final Calculation Sheet'!$J$4) | O18: =SUM(B18:N18)
A19: TCS @ 2% (₹) | B19: =IF('Final Calculation Sheet'!$K$4="","",'Final Calculation Sheet'!$K$4) | O19: =SUM(B19:N19)
A20: TDS u/s 194(O) (₹) | B20: =IF('Final Calculation Sheet'!$L$4="","",'Final Calculation Sheet'!$L$4) | O20: =SUM(B20:N20)
A21: Service Charge gross (₹) | B21: =IF('Final Calculation Sheet'!$M$4="","",'Final Calculation Sheet'!$M$4) | O21: =SUM(B21:N21)
A22: TDS u/s 194(H) (₹) | B22: =IF('Final Calculation Sheet'!$N$4="","",'Final Calculation Sheet'!$N$4) | O22: =SUM(B22:N22)
A23: Net Service Charge (₹) | B23: =IF('Final Calculation Sheet'!$O$4="","",'Final Calculation Sheet'!$O$4) | O23: =SUM(B23:N23)
A24: Svc Charge to MSTC (₹) | B24: =IF('Final Calculation Sheet'!$P$4="","",'Final Calculation Sheet'!$P$4) | O24: =SUM(B24:N24)
A25: GST TDS Rate | B25: =IF('Final Calculation Sheet'!$Q$4="","",'Final Calculation Sheet'!$Q$4) | O25: –
A26: GST TDS (₹) | B26: =IF('Final Calculation Sheet'!$R$4="","",'Final Calculation Sheet'!$R$4) | O26: =SUM(B26:N26)
A27: Total Receivables (₹) | B27: =IF('Final Calculation Sheet'!$S$4="","",'Final Calculation Sheet'!$S$4) | O27: =SUM(B27:N27)
A28: ▸ SECURITY DEPOSIT
A29: SD Expected (₹) | B29: =IF('Final Calculation Sheet'!$T$4="","",'Final Calculation Sheet'!$T$4) | O29: =SUM(B29:N29)
A30: SD Received (₹) | B30: =IF('Final Calculation Sheet'!$U$4="","",'Final Calculation Sheet'!$U$4) | O30: =SUM(B30:N30)
A31: SD Receipt Date | B31: =IF('Final Calculation Sheet'!$V$4="","",'Final Calculation Sheet'!$V$4) | O31: –
A32: ▸ FINAL PAYMENT
A33: FP Expected (₹) | B33: =IF('Final Calculation Sheet'!$W$4="","",'Final Calculation Sheet'!$W$4) | O33: =SUM(B33:N33)
A34: FP Received (₹) | B34: =IF('Final Calculation Sheet'!$X$4="","",'Final Calculation Sheet'!$X$4) | O34: =SUM(B34:N34)
A35: FP Receipt Date | B35: =IF('Final Calculation Sheet'!$Y$4="","",'Final Calculation Sheet'!$Y$4) | O35: –
A36: ▸ LPP
A37: LPP Expected (₹) | B37: =IF('Final Calculation Sheet'!$Z$4="","",'Final Calculation Sheet'!$Z$4) | O37: =SUM(B37:N37)
A38: LPP Received (₹) | B38: =IF('Final Calculation Sheet'!$AA$4="","",'Final Calculation Sheet'!$AA$4) | O38: =SUM(B38:N38)
A39: LPP Receipt Date | B39: =IF('Final Calculation Sheet'!$AB$4="","",'Final Calculation Sheet'!$AB$4) | O39: –
A40: ▸ SUMMARY
A41: Total Received (₹) | B41: =IF('Final Calculation Sheet'!$AC$4="","",'Final Calculation Sheet'!$AC$4) | O41: =SUM(B41:N41)
...

Sheet Collapsible - Lots Down
A1: MSTC LIMITED • BUYER × LOT COLLAPSIBLE VIEW (lots ↓ rows | fields → columns)
A2: HOW TO USE ▶ the − / + buttons in the left margin fold a buyer: its lots hide and the banner plus the ∑ totals row stay on screen • the − above a column category (LOT INFO, FINANCIALS …) folds those columns away, keeping the category's first column • every figure is a live link to 'Final Calculation Sheet' • for filtering use 'Ledger Filter - Lots Down' or 'Ledger Filter - Lots Across'
A3: LOT INFORMATION | G3: FINANCIALS | S3: SECURITY DEPOSIT | V3: FINAL PAYMENT | Y3: LPP | AB3: SUMMARY | AE3: DOCUMENT
A4: Lot No. | B4: Lot Name | C4: Bid Sheet / Auction | D4: Quantity | E4: Unit | F4: Rate (₹) | G4: Mat. Value (₹) | H4: GST @ 18% (₹) | I4: Mat. Value + GST (₹) | J4: TCS @ 2% (₹) | K4: TDS u/s 194(O) (₹) | L4: Service Charge gross (₹) | M4: TDS u/s 194(H) (₹) | N4: Net Service Charge (₹) | O4: Svc Charge to MSTC (₹) | P4: GST TDS Rate | Q4: GST TDS (₹) | R4: Total Receivables (₹) | S4: SD Expected (₹) | T4: SD Received (₹) | U4: SD Receipt Date | V4: FP Expected (₹) | W4: FP Received (₹) | X4: FP Receipt Date | Y4: LPP Expected (₹) | Z4: LPP Received (₹) | AA4: LPP Receipt Date | AB4: Total Received (₹) | AC4: Outstanding (₹) | AD4: Payment Status | AE4: Invoice No. | AF4: SAP Document | AG4: Doc./Invoice Date
A5: ="▼ AL HAMD TRADE CORPORATION • "&COUNTIF('Final Calculation Sheet'!$G$4:$G$1000,"AL HAMD TRADE CORPORATION")&" LOT(S) • MAT. VALUE ₹"&TEXT(SUMIF('Final Calculation Sheet'!$G$4:$G$1000,"AL HAMD TRADE CORPORATION",'Final Calculation Sheet'!$H$4:$H$1000),"#,##0")&" • RECEIVED ₹"&TEXT(SUMIF('Final Calculation Sheet'!$G$4:$G$1000,"AL HAMD TRADE CORPORATION",'Final Calculation Sheet'!$AC$4:$AC$1000),"#,##0")&" • OUTSTANDING ₹"&TEXT(SUMIF('Final Calculation Sheet'!$G$4:$G$1000,"AL HAMD TRADE CORPORATION",'Final Calculation Sheet'!$AD$4:$AD$1000),"#,##0")
A6: =IF('Final Calculation Sheet'!$F$4="","",'Final Calculation Sheet'!$F$4) | B6: =IF('Final Calculation Sheet'!$B$4="","",'Final Calculation Sheet'!$B$4) | C6: =IF('Final Calculation Sheet'!$D$4="","",'Final Calculation Sheet'!$D$4) | D6: =IF('Final Calculation Sheet'!$A$4="","",'Final Calculation Sheet'!$A$4) | E6: =IF('Final Calculation Sheet'!$E$4="","",'Final Calculation Sheet'!$E$4) | F6: =IF('Final Calculation Sheet'!$C$4="","",'Final Calculation Sheet'!$C$4) | G6: =IF('Final Calculation Sheet'!$H$4="","",'Final Calculation Sheet'!$H$4) | H6: =IF('Final Calculation Sheet'!$I$4="","",'Final Calculation Sheet'!$I$4) | I6: =IF('Final Calculation Sheet'!$J$4="","",'Final Calculation Sheet'!$J$4) | J6: =IF('Final Calculation Sheet'!$K$4="","",'Final Calculation Sheet'!$K$4) | K6: =IF('Final Calculation Sheet'!$L$4="","",'Final Calculation Sheet'!$L$4) | L6: =IF('Final Calculation Sheet'!$M$4="","",'Final Calculation Sheet'!$M$4) | M6: =IF('Final Calculation Sheet'!$N$4="","",'Final Calculation Sheet'!$N$4) | N6: =IF('Final Calculation Sheet'!$O$4="","",'Final Calculation Sheet'!$O$4) | O6: =IF('Final Calculation Sheet'!$P$4="","",'Final Calculation Sheet'!$P$4) | P6: =IF('Final Calculation Sheet'!$Q$4="","",'Final Calculation Sheet'!$Q$4) | Q6: =IF('Final Calculation Sheet'!$R$4="","",'Final Calculation Sheet'!$R$4) | R6: =IF('Final Calculation Sheet'!$S$4="","",'Final Calculation Sheet'!$S$4) | S6: =IF('Final Calculation Sheet'!$T$4="","",'Final Calculation Sheet'!$T$4) | T6: =IF('Final Calculation Sheet'!$U$4="","",'Final Calculation Sheet'!$U$4) | U6: =IF('Final Calculation Sheet'!$V$4="","",'Final Calculation Sheet'!$V$4) | V6: =IF('Final Calculation Sheet'!$W$4="","",'Final Calculation Sheet'!$W$4) | W6: =IF('Final Calculation Sheet'!$X$4="","",'Final Calculation Sheet'!$X$4) | X6: =IF('Final Calculation Sheet'!$Y$4="","",'Final Calculation Sheet'!$Y$4) | Y6: =IF('Final Calculation Sheet'!$Z$4="","",'Final Calculation Sheet'!$Z$4) | Z6: =IF('Final Calculation Sheet'!$AA$4="","",'Final Calculation Sheet'!$AA$4) | AA6: =IF('Final Calculation Sheet'!$AB$4="","",'Final Calculation Sheet'!$AB$4) | AB6: =IF('Final Calculation Sheet'!$AC$4="","",'Final Calculation Sheet'!$AC$4) | AC6: =IF('Final Calculation Sheet'!$AD$4="","",'Final Calculation Sheet'!$AD$4) | AD6: =IF('Final Calculation Sheet'!$AD$4="","",IF('Final Calculation Sheet'!$AD$4<=0,"SETTLED","OUTSTANDING")) | AE6: =IF('Final Calculation Sheet'!$AE$4="","",'Final Calculation Sheet'!$AE$4) | AF6: =IF('Final Calculation Sheet'!$AF$4="","",'Final Calculation Sheet'!$AF$4) | AG6: =IF('Final Calculation Sheet'!$AG$4="","",'Final Calculation Sheet'!$AG$4)
A7: ∑ AL HAMD TRADE CORPORATION — TOTALS | B7: – | C7: – | D7: =SUM(D6:D6) | E7: – | F7: – | G7: =SUM(G6:G6) | H7: =SUM(H6:H6) | I7: =SUM(I6:I6) | J7: =SUM(J6:J6) | K7: =SUM(K6:K6) | L7: =SUM(L6:L6) | M7: =SUM(M6:M6) | N7: =SUM(N6:N6) | O7: =SUM(O6:O6) | P7: – | Q7: =SUM(Q6:Q6) | R7: =SUM(R6:R6) | S7: =SUM(S6:S6) | T7: =SUM(T6:T6) | U7: – | V7: =SUM(V6:V6) | W7: =SUM(W6:W6) | X7: – | Y7: =SUM(Y6:Y6) | Z7: =SUM(Z6:Z6) | AA7: – | AB7: =SUM(AB6:AB6) | AC7: =SUM(AC6:AC6) | AD7: – | AE7: – | AF7: – | AG7: –
A9: ="▼ F R KHANS ENTERPRISES • "&COUNTIF('Final Calculation Sheet'!$G$4:$G$1000,"F R KHANS ENTERPRISES")&" LOT(S) • MAT. VALUE ₹"&TEXT(SUMIF('Final Calculation Sheet'!$G$4:$G$1000,"F R KHANS ENTERPRISES",'Final Calculation Sheet'!$H$4:$H$1000),"#,##0")&" • RECEIVED ₹"&TEXT(SUMIF('Final Calculation Sheet'!$G$4:$G$1000,"F R KHANS ENTERPRISES",'Final Calculation Sheet'!$AC$4:$AC$1000),"#,##0")&" • OUTSTANDING ₹"&TEXT(SUMIF('Final Calculation Sheet'!$G$4:$G$1000,"F R KHANS ENTERPRISES",'Final Calculation Sheet'!$AD$4:$AD$1000),"#,##0")
A10: =IF('Final Calculation Sheet'!$F$6="","",'Final Calculation Sheet'!$F$6) | B10: =IF('Final Calculation Sheet'!$B$6="","",'Final Calculation Sheet'!$B$6) | C10: =IF('Final Calculation Sheet'!$D$6="","",'Final Calculation Sheet'!$D$6) | D10: =IF('Final Calculation Sheet'!$A$6="","",'Final Calculation Sheet'!$A$6) | E10: =IF('Final Calculation Sheet'!$E$6="","",'Final Calculation Sheet'!$E$6) | F10: =IF('Final Calculation Sheet'!$C$6="","",'Final Calculation Sheet'!$C$6) | G10: =IF('Final Calculation Sheet'!$H$6="","",'Final Calculation Sheet'!$H$6) | H10: =IF('Final Calculation Sheet'!$I$6="","",'Final Calculation Sheet'!$I$6) | I10: =IF('Final Calculation Sheet'!$J$6="","",'Final Calculation Sheet'!$J$6) | J10: =IF('Final Calculation Sheet'!$K$6="","",'Final Calculation Sheet'!$K$6) | K10: =IF('Final Calculation Sheet'!$L$6="","",'Final Calculation Sheet'!$L$6) | L10: =IF('Final Calculation Sheet'!$M$6="","",'Final Calculation Sheet'!$M$6) | M10: =IF('Final Calculation Sheet'!$N$6="","",'Final Calculation Sheet'!$N$6) | N10: =IF('Final Calculation Sheet'!$O$6="","",'Final Calculation Sheet'!$O$6) | O10: =IF('Final Calculation Sheet'!$P$6="","",'Final Calculation Sheet'!$P$6) | P10: =IF('Final Calculation Sheet'!$Q$6="","",'Final Calculation Sheet'!$Q$6) | Q10: =IF('Final Calculation Sheet'!$R$6="","",'Final Calculation Sheet'!$R$6) | R10: =IF('Final Calculation Sheet'!$S$6="","",'Final Calculation Sheet'!$S$6) | S10: =IF('Final Calculation Sheet'!$T$6="","",'Final Calculation Sheet'!$T$6) | T10: =IF('Final Calculation Sheet'!$U$6="","",'Final Calculation Sheet'!$U$6) | U10: =IF('Final Calculation Sheet'!$V$6="","",'Final Calculation Sheet'!$V$6) | V10: =IF('Final Calculation Sheet'!$W$6="","",'Final Calculation Sheet'!$W$6) | W10: =IF('Final Calculation Sheet'!$X$6="","",'Final Calculation Sheet'!$X$6) | X10: =IF('Final Calculation Sheet'!$Y$6="","",'Final Calculation Sheet'!$Y$6) | Y10: =IF('Final Calculation Sheet'!$Z$6="","",'Final Calculation Sheet'!$Z$6) | Z10: =IF('Final Calculation Sheet'!$AA$6="","",'Final Calculation Sheet'!$AA$6) | AA10: =IF('Final Calculation Sheet'!$AB$6="","",'Final Calculation Sheet'!$AB$6) | AB10: =IF('Final Calculation Sheet'!$AC$6="","",'Final Calculation Sheet'!$AC$6) | AC10: =IF('Final Calculation Sheet'!$AD$6="","",'Final Calculation Sheet'!$AD$6) | AD10: =IF('Final Calculation Sheet'!$AD$6="","",IF('Final Calculation Sheet'!$AD$6<=0,"SETTLED","OUTSTANDING")) | AE10: =IF('Final Calculation Sheet'!$AE$6="","",'Final Calculation Sheet'!$AE$6) | AF10: =IF('Final Calculation Sheet'!$AF$6="","",'Final Calculation Sheet'!$AF$6) | AG10: =IF('Final Calculation Sheet'!$AG$6="","",'Final Calculation Sheet'!$AG$6)
A11: =IF('Final Calculation Sheet'!$F$7="","",'Final Calculation Sheet'!$F$7) | B11: =IF('Final Calculation Sheet'!$B$7="","",'Final Calculation Sheet'!$B$7) | C11: =IF('Final Calculation Sheet'!$D$7="","",'Final Calculation Sheet'!$D$7) | D11: =IF('Final Calculation Sheet'!$A$7="","",'Final Calculation Sheet'!$A$7) | E11: =IF('Final Calculation Sheet'!$E$7="","",'Final Calculation Sheet'!$E$7) | F11: =IF('Final Calculation Sheet'!$C$7="","",'Final Calculation Sheet'!$C$7) | G11: =IF('Final Calculation Sheet'!$H$7="","",'Final Calculation Sheet'!$H$7) | H11: =IF('Final Calculation Sheet'!$I$7="","",'Final Calculation Sheet'!$I$7) | I11: =IF('Final Calculation Sheet'!$J$7="","",'Final Calculation Sheet'!$J$7) | J11: =IF('Final Calculation Sheet'!$K$7="","",'Final Calculation Sheet'!$K$7) | K11: =IF('Final Calculation Sheet'!$L$7="","",'Final Calculation Sheet'!$L$7) | L11: =IF('Final Calculation Sheet'!$M$7="","",'Final Calculation Sheet'!$M$7) | M11: =IF('Final Calculation Sheet'!$N$7="","",'Final Calculation Sheet'!$N$7) | N11: =IF('Final Calculation Sheet'!$O$7="","",'Final Calculation Sheet'!$O$7) | O11: =IF('Final Calculation Sheet'!$P$7="","",'Final Calculation Sheet'!$P$7) | P11: =IF('Final Calculation Sheet'!$Q$7="","",'Final Calculation Sheet'!$Q$7) | Q11: =IF('Final Calculation Sheet'!$R$7="","",'Final Calculation Sheet'!$R$7) | R11: =IF('Final Calculation Sheet'!$S$7="","",'Final Calculation Sheet'!$S$7) | S11: =IF('Final Calculation Sheet'!$T$7="","",'Final Calculation Sheet'!$T$7) | T11: =IF('Final Calculation Sheet'!$U$7="","",'Final Calculation Sheet'!$U$7) | U11: =IF('Final Calculation Sheet'!$V$7="","",'Final Calculation Sheet'!$V$7) | V11: =IF('Final Calculation Sheet'!$W$7="","",'Final Calculation Sheet'!$W$7) | W11: =IF('Final Calculation Sheet'!$X$7="","",'Final Calculation Sheet'!$X$7) | X11: =IF('Final Calculation Sheet'!$Y$7="","",'Final Calculation Sheet'!$Y$7) | Y11: =IF('Final Calculation Sheet'!$Z$7="","",'Final Calculation Sheet'!$Z$7) | Z11: =IF('Final Calculation Sheet'!$AA$7="","",'Final Calculation Sheet'!$AA$7) | AA11: =IF('Final Calculation Sheet'!$AB$7="","",'Final Calculation Sheet'!$AB$7) | AB11: =IF('Final Calculation Sheet'!$AC$7="","",'Final Calculation Sheet'!$AC$7) | AC11: =IF('Final Calculation Sheet'!$AD$7="","",'Final Calculation Sheet'!$AD$7) | AD11: =IF('Final Calculation Sheet'!$AD$7="","",IF('Final Calculation Sheet'!$AD$7<=0,"SETTLED","OUTSTANDING")) | AE11: =IF('Final Calculation Sheet'!$AE$7="","",'Final Calculation Sheet'!$AE$7) | AF11: =IF('Final Calculation Sheet'!$AF$7="","",'Final Calculation Sheet'!$AF$7) | AG11: =IF('Final Calculation Sheet'!$AG$7="","",'Final Calculation Sheet'!$AG$7)
A12: ∑ F R KHANS ENTERPRISES — TOTALS | B12: – | C12: – | D12: =SUM(D10:D11) | E12: – | F12: – | G12: =SUM(G10:G11) | H12: =SUM(H10:H11) | I12: =SUM(I10:I11) | J12: =SUM(J10:J11) | K12: =SUM(K10:K11) | L12: =SUM(L10:L11) | M12: =SUM(M10:M11) | N12: =SUM(N10:N11) | O12: =SUM(O10:O11) | P12: – | Q12: =SUM(Q10:Q11) | R12: =SUM(R10:R11) | S12: =SUM(S10:S11) | T12: =SUM(T10:T11) | U12: – | V12: =SUM(V10:V11) | W12: =SUM(W10:W11) | X12: – | Y12: =SUM(Y10:Y11) | Z12: =SUM(Z10:Z11) | AA12: – | AB12: =SUM(AB10:AB11) | AC12: =SUM(AC10:AC11) | AD12: – | AE12: – | AF12: – | AG12: –
A14: ="▼ HIND TRADERS • "&COUNTIF('Final Calculation Sheet'!$G$4:$G$1000,"HIND TRADERS")&" LOT(S) • MAT. VALUE ₹"&TEXT(SUMIF('Final Calculation Sheet'!$G$4:$G$1000,"HIND TRADERS",'Final Calculation Sheet'!$H$4:$H$1000),"#,##0")&" • RECEIVED ₹"&TEXT(SUMIF('Final Calculation Sheet'!$G$4:$G$1000,"HIND TRADERS",'Final Calculation Sheet'!$AC$4:$AC$1000),"#,##0")&" • OUTSTANDING ₹"&TEXT(SUMIF('Final Calculation Sheet'!$G$4:$G$1000,"HIND TRADERS",'Final Calculation Sheet'!$AD$4:$AD$1000),"#,##0")
A15: =IF('Final Calculation Sheet'!$F$15="","",'Final Calculation Sheet'!$F$15) | B15: =IF('Final Calculation Sheet'!$B$15="","",'Final Calculation Sheet'!$B$15) | C15: =IF('Final Calculation Sheet'!$D$15="","",'Final Calculation Sheet'!$D$15) | D15: =IF('Final Calculation Sheet'!$A$15="","",'Final Calculation Sheet'!$A$15) | E15: =IF('Final Calculation Sheet'!$E$15="","",'Final Calculation Sheet'!$E$15) | F15: =IF('Final Calculation Sheet'!$C$15="","",'Final Calculation Sheet'!$C$15) | G15: =IF('Final Calculation Sheet'!$H$15="","",'Final Calculation Sheet'!$H$15) | H15: =IF('Final Calculation Sheet'!$I$15="","",'Final Calculation Sheet'!$I$15) | I15: =IF('Final Calculation Sheet'!$J$15="","",'Final Calculation Sheet'!$J$15) | J15: =IF('Final Calculation Sheet'!$K$15="","",'Final Calculation Sheet'!$K$15) | K15: =IF('Final Calculation Sheet'!$L$15="","",'Final Calculation Sheet'!$L$15) | L15: =IF('Final Calculation Sheet'!$M$15="","",'Final Calculation Sheet'!$M$15) | M15: =IF('Final Calculation Sheet'!$N$15="","",'Final Calculation Sheet'!$N$15) | N15: =IF('Final Calculation Sheet'!$O$15="","",'Final Calculation Sheet'!$O$15) | O15: =IF('Final Calculation Sheet'!$P$15="","",'Final Calculation Sheet'!$P$15) | P15: =IF('Final Calculation Sheet'!$Q$15="","",'Final Calculation Sheet'!$Q$15) | Q15: =IF('Final Calculation Sheet'!$R$15="","",'Final Calculation Sheet'!$R$15) | R15: =IF('Final Calculation Sheet'!$S$15="","",'Final Calculation Sheet'!$S$15) | S15: =IF('Final Calculation Sheet'!$T$15="","",'Final Calculation Sheet'!$T$15) | T15: =IF('Final Calculation Sheet'!$U$15="","",'Final Calculation Sheet'!$U$15) | U15: =IF('Final Calculation Sheet'!$V$15="","",'Final Calculation Sheet'!$V$15) | V15: =IF('Final Calculation Sheet'!$W$15="","",'Final Calculation Sheet'!$W$15) | W15: =IF('Final Calculation Sheet'!$X$15="","",'Final Calculation Sheet'!$X$15) | X15: =IF('Final Calculation Sheet'!$Y$15="","",'Final Calculation Sheet'!$Y$15) | Y15: =IF('Final Calculation Sheet'!$Z$15="","",'Final Calculation Sheet'!$Z$15) | Z15: =IF('Final Calculation Sheet'!$AA$15="","",'Final Calculation Sheet'!$AA$15) | AA15: =IF('Final Calculation Sheet'!$AB$15="","",'Final Calculation Sheet'!$AB$15) | AB15: =IF('Final Calculation Sheet'!$AC$15="","",'Final Calculation Sheet'!$AC$15) | AC15: =IF('Final Calculation Sheet'!$AD$15="","",'Final Calculation Sheet'!$AD$15) | AD15: =IF('Final Calculation Sheet'!$AD$15="","",IF('Final Calculation Sheet'!$AD$15<=0,"SETTLED","OUTSTANDING")) | AE15: =IF('Final Calculation Sheet'!$AE$15="","",'Final Calculation Sheet'!$AE$15) | AF15: =IF('Final Calculation Sheet'!$AF$15="","",'Final Calculation Sheet'!$AF$15) | AG15: =IF('Final Calculation Sheet'!$AG$15="","",'Final Calculation Sheet'!$AG$15)
A16: ∑ HIND TRADERS — TOTALS | B16: – | C16: – | D16: =SUM(D15:D15) | E16: – | F16: – | G16: =SUM(G15:G15) | H16: =SUM(H15:H15) | I16: =SUM(I15:I15) | J16: =SUM(J15:J15) | K16: =SUM(K15:K15) | L16: =SUM(L15:L15) | M16: =SUM(M15:M15) | N16: =SUM(N15:N15) | O16: =SUM(O15:O15) | P16: – | Q16: =SUM(Q15:Q15) | R16: =SUM(R15:R15) | S16: =SUM(S15:S15) | T16: =SUM(T15:T15) | U16: – | V16: =SUM(V15:V15) | W16: =SUM(W15:W15) | X16: – | Y16: =SUM(Y15:Y15) | Z16: =SUM(Z15:Z15) | AA16: – | AB16: =SUM(AB15:AB15) | AC16: =SUM(AC15:AC15) | AD16: – | AE16: – | AF16: – | AG16: –
A18: ="▼ KASHYAP TRADING CO • "&COUNTIF('Final Calculation Sheet'!$G$4:$G$1000,"KASHYAP TRADING CO")&" LOT(S) • MAT. VALUE ₹"&TEXT(SUMIF('Final Calculation Sheet'!$G$4:$G$1000,"KASHYAP TRADING CO",'Final Calculation Sheet'!$H$4:$H$1000),"#,##0")&" • RECEIVED ₹"&TEXT(SUMIF('Final Calculation Sheet'!$G$4:$G$1000,"KASHYAP TRADING CO",'Final Calculation Sheet'!$AC$4:$AC$1000),"#,##0")&" • OUTSTANDING ₹"&TEXT(SUMIF('Final Calculation Sheet'!$G$4:$G$1000,"KASHYAP TRADING CO",'Final Calculation Sheet'!$AD$4:$AD$1000),"#,##0")
A19: =IF('Final Calculation Sheet'!$F$38="","",'Final Calculation Sheet'!$F$38) | B19: =IF('Final Calculation Sheet'!$B$38="","",'Final Calculation Sheet'!$B$38) | C19: =IF('Final Calculation Sheet'!$D$38="","",'Final Calculation Sheet'!$D$38) | D19: =IF('Final Calculation Sheet'!$A$38="","",'Final Calculation Sheet'!$A$38) | E19: =IF('Final Calculation Sheet'!$E$38="","",'Final Calculation Sheet'!$E$38) | F19: =IF('Final Calculation Sheet'!$C$38="","",'Final Calculation Sheet'!$C$38) | G19: =IF('Final Calculation Sheet'!$H$38="","",'Final Calculation Sheet'!$H$38) | H19: =IF('Final Calculation Sheet'!$I$38="","",'Final Calculation Sheet'!$I$38) | I19: =IF('Final Calculation Sheet'!$J$38="","",'Final Calculation Sheet'!$J$38) | J19: =IF('Final Calculation Sheet'!$K$38="","",'Final Calculation Sheet'!$K$38) | K19: =IF('Final Calculation Sheet'!$L$38="","",'Final Calculation Sheet'!$L$38) | L19: =IF('Final Calculation Sheet'!$M$38="","",'Final Calculation Sheet'!$M$38) | M19: =IF('Final Calculation Sheet'!$N$38="","",'Final Calculation Sheet'!$N$38) | N19: =IF('Final Calculation Sheet'!$O$38="","",'Final Calculation Sheet'!$O$38) | O19: =IF('Final Calculation Sheet'!$P$38="","",'Final Calculation Sheet'!$P$38) | P19: =IF('Final Calculation Sheet'!$Q$38="","",'Final Calculation Sheet'!$Q$38) | Q19: =IF('Final Calculation Sheet'!$R$38="","",'Final Calculation Sheet'!$R$38) | R19: =IF('Final Calculation Sheet'!$S$38="","",'Final Calculation Sheet'!$S$38) | S19: =IF('Final Calculation Sheet'!$T$38="","",'Final Calculation Sheet'!$T$38) | T19: =IF('Final Calculation Sheet'!$U$38="","",'Final Calculation Sheet'!$U$38) | U19: =IF('Final Calculation Sheet'!$V$38="","",'Final Calculation Sheet'!$V$38) | V19: =IF('Final Calculation Sheet'!$W$38="","",'Final Calculation Sheet'!$W$38) | W19: =IF('Final Calculation Sheet'!$X$38="","",'Final Calculation Sheet'!$X$38) | X19: =IF('Final Calculation Sheet'!$Y$38="","",'Final Calculation Sheet'!$Y$38) | Y19: =IF('Final Calculation Sheet'!$Z$38="","",'Final Calculation Sheet'!$Z$38) | Z19: =IF('Final Calculation Sheet'!$AA$38="","",'Final Calculation Sheet'!$AA$38) | AA19: =IF('Final Calculation Sheet'!$AB$38="","",'Final Calculation Sheet'!$AB$38) | AB19: =IF('Final Calculation Sheet'!$AC$38="","",'Final Calculation Sheet'!$AC$38) | AC19: =IF('Final Calculation Sheet'!$AD$38="","",'Final Calculation Sheet'!$AD$38) | AD19: =IF('Final Calculation Sheet'!$AD$38="","",IF('Final Calculation Sheet'!$AD$38<=0,"SETTLED","OUTSTANDING")) | AE19: =IF('Final Calculation Sheet'!$AE$38="","",'Final Calculation Sheet'!$AE$38) | AF19: =IF('Final Calculation Sheet'!$AF$38="","",'Final Calculation Sheet'!$AF$38) | AG19: =IF('Final Calculation Sheet'!$AG$38="","",'Final Calculation Sheet'!$AG$38)
A20: ∑ KASHYAP TRADING CO — TOTALS | B20: – | C20: – | D20: =SUM(D19:D19) | E20: – | F20: – | G20: =SUM(G19:G19) | H20: =SUM(H19:H19) | I20: =SUM(I19:I19) | J20: =SUM(J19:J19) | K20: =SUM(K19:K19) | L20: =SUM(L19:L19) | M20: =SUM(M19:M19) | N20: =SUM(N19:N19) | O20: =SUM(O19:O19) | P20: – | Q20: =SUM(Q19:Q19) | R20: =SUM(R19:R19) | S20: =SUM(S19:S19) | T20: =SUM(T19:T19) | U20: – | V20: =SUM(V19:V19) | W20: =SUM(W19:W19) | X20: – | Y20: =SUM(Y19:Y19) | Z20: =SUM(Z19:Z19) | AA20: – | AB20: =SUM(AB19:AB19) | AC20: =SUM(AC19:AC19) | AD20: – | AE20: – | AF20: – | AG20: –
A22: ="▼ M I SCRAP TRADERS • "&COUNTIF('Final Calculation Sheet'!$G$4:$G$1000,"M I SCRAP TRADERS")&" LOT(S) • MAT. VALUE ₹"&TEXT(SUMIF('Final Calculation Sheet'!$G$4:$G$1000,"M I SCRAP TRADERS",'Final Calculation Sheet'!$H$4:$H$1000),"#,##0")&" • RECEIVED ₹"&TEXT(SUMIF('Final Calculation Sheet'!$G$4:$G$1000,"M I SCRAP TRADERS",'Final Calculation Sheet'!$AC$4:$AC$1000),"#,##0")&" • OUTSTANDING ₹"&TEXT(SUMIF('Final Calculation Sheet'!$G$4:$G$1000,"M I SCRAP TRADERS",'Final Calculation Sheet'!$AD$4:$AD$1000),"#,##0")
A23: =IF('Final Calculation Sheet'!$F$27="","",'Final Calculation Sheet'!$F$27) | B23: =IF('Final Calculation Sheet'!$B$27="","",'Final Calculation Sheet'!$B$27) | C23: =IF('Final Calculation Sheet'!$D$27="","",'Final Calculation Sheet'!$D$27) | D23: =IF('Final Calculation Sheet'!$A$27="","",'Final Calculation Sheet'!$A$27) | E23: =IF('Final Calculation Sheet'!$E$27="","",'Final Calculation Sheet'!$E$27) | F23: =IF('Final Calculation Sheet'!$C$27="","",'Final Calculation Sheet'!$C$27) | G23: =IF('Final Calculation Sheet'!$H$27="","",'Final Calculation Sheet'!$H$27) | H23: =IF('Final Calculation Sheet'!$I$27="","",'Final Calculation Sheet'!$I$27) | I23: =IF('Final Calculation Sheet'!$J$27="","",'Final Calculation Sheet'!$J$27) | J23: =IF('Final Calculation Sheet'!$K$27="","",'Final Calculation Sheet'!$K$27) | K23: =IF('Final Calculation Sheet'!$L$27="","",'Final Calculation Sheet'!$L$27) | L23: =IF('Final Calculation Sheet'!$M$27="","",'Final Calculation Sheet'!$M$27) | M23: =IF('Final Calculation Sheet'!$N$27="","",'Final Calculation Sheet'!$N$27) | N23: =IF('Final Calculation Sheet'!$O$27="","",'Final Calculation Sheet'!$O$27) | O23: =IF('Final Calculation Sheet'!$P$27="","",'Final Calculation Sheet'!$P$27) | P23: =IF('Final Calculation Sheet'!$Q$27="","",'Final Calculation Sheet'!$Q$27) | Q23: =IF('Final Calculation Sheet'!$R$27="","",'Final Calculation Sheet'!$R$27) | R23: =IF('Final Calculation Sheet'!$S$27="","",'Final Calculation Sheet'!$S$27) | S23: =IF('Final Calculation Sheet'!$T$27="","",'Final Calculation Sheet'!$T$27) | T23: =IF('Final Calculation Sheet'!$U$27="","",'Final Calculation Sheet'!$U$27) | U23: =IF('Final Calculation Sheet'!$V$27="","",'Final Calculation Sheet'!$V$27) | V23: =IF('Final Calculation Sheet'!$W$27="","",'Final Calculation Sheet'!$W$27) | W23: =IF('Final Calculation Sheet'!$X$27="","",'Final Calculation Sheet'!$X$27) | X23: =IF('Final Calculation Sheet'!$Y$27="","",'Final Calculation Sheet'!$Y$27) | Y23: =IF('Final Calculation Sheet'!$Z$27="","",'Final Calculation Sheet'!$Z$27) | Z23: =IF('Final Calculation Sheet'!$AA$27="","",'Final Calculation Sheet'!$AA$27) | AA23: =IF('Final Calculation Sheet'!$AB$27="","",'Final Calculation Sheet'!$AB$27) | AB23: =IF('Final Calculation Sheet'!$AC$27="","",'Final Calculation Sheet'!$AC$27) | AC23: =IF('Final Calculation Sheet'!$AD$27="","",'Final Calculation Sheet'!$AD$27) | AD23: =IF('Final Calculation Sheet'!$AD$27="","",IF('Final Calculation Sheet'!$AD$27<=0,"SETTLED","OUTSTANDING")) | AE23: =IF('Final Calculation Sheet'!$AE$27="","",'Final Calculation Sheet'!$AE$27) | AF23: =IF('Final Calculation Sheet'!$AF$27="","",'Final Calculation Sheet'!$AF$27) | AG23: =IF('Final Calculation Sheet'!$AG$27="","",'Final Calculation Sheet'!$AG$27)
