Workbook

Sheet Buyer Pivot
A1: MSTC LIMITED — Buyer-wise Lot Details
A2: ▶ Select Buyer: | B2: AL HAMD TRADE CORPORATION | C2: ← Click cell to pick buyer from dropdown
A3: Buyer Name: | B3: =B2 -> AL HAMD TRADE CORPORATION
A4: Field | B4: Lot 1 | C4: Lot 2 | D4: Lot 3 | E4: Lot 4 | F4: Lot 5 | G4: Lot 6 | H4: Lot 7 | I4: Lot 8 | J4: Lot 9 | K4: Lot 10 | L4: Lot 11 | M4: Lot 12 | N4: Lot 13
A5: LOT INFORMATION
A6: Lot No. | B6: =IFERROR(INDIRECT("'Final Calculation Sheet'!$F"&INDEX('Buyer Lookup'!$A:$AZ,MATCH($B$2,'Buyer Lookup'!$A:$A,0),2)),"") -> 1763 | C6: =IFERROR(INDIRECT("'Final Calculation Sheet'!$F"&INDEX('Buyer Lookup'!$A:$AZ,MATCH($B$2,'Buyer Lookup'!$A:$A,0),3)),"") -> 0 | D6: =IFERROR(INDIRECT("'Final Calculation Sheet'!$F"&INDEX('Buyer Lookup'!$A:$AZ,MATCH($B$2,'Buyer Lookup'!$A:$A,0),4)),"") | E6: =IFERROR(INDIRECT("'Final Calculation Sheet'!$F"&INDEX('Buyer Lookup'!$A:$AZ,MATCH($B$2,'Buyer Lookup'!$A:$A,0),5)),"") | F6: =IFERROR(INDIRECT("'Final Calculation Sheet'!$F"&INDEX('Buyer Lookup'!$A:$AZ,MATCH($B$2,'Buyer Lookup'!$A:$A,0),6)),"") | G6: =IFERROR(INDIRECT("'Final Calculation Sheet'!$F"&INDEX('Buyer Lookup'!$A:$AZ,MATCH($B$2,'Buyer Lookup'!$A:$A,0),7)),"") | H6: =IFERROR(INDIRECT("'Final Calculation Sheet'!$F"&INDEX('Buyer Lookup'!$A:$AZ,MATCH($B$2,'Buyer Lookup'!$A:$A,0),8)),"") | I6: =IFERROR(INDIRECT("'Final Calculation Sheet'!$F"&INDEX('Buyer Lookup'!$A:$AZ,MATCH($B$2,'Buyer Lookup'!$A:$A,0),9)),"") | J6: =IFERROR(INDIRECT("'Final Calculation Sheet'!$F"&INDEX('Buyer Lookup'!$A:$AZ,MATCH($B$2,'Buyer Lookup'!$A:$A,0),10)),"") | K6: =IFERROR(INDIRECT("'Final Calculation Sheet'!$F"&INDEX('Buyer Lookup'!$A:$AZ,MATCH($B$2,'Buyer Lookup'!$A:$A,0),11)),"") | L6: =IFERROR(INDIRECT("'Final Calculation Sheet'!$F"&INDEX('Buyer Lookup'!$A:$AZ,MATCH($B$2,'Buyer Lookup'!$A:$A,0),12)),"") | M6: =IFERROR(INDIRECT("'Final Calculation Sheet'!$F"&INDEX('Buyer Lookup'!$A:$AZ,MATCH($B$2,'Buyer Lookup'!$A:$A,0),13)),"") | N6: =IFERROR(INDIRECT("'Final Calculation Sheet'!$F"&INDEX('Buyer Lookup'!$A:$AZ,MATCH($B$2,'Buyer Lookup'!$A:$A,0),14)),"")
A7: Lot Name | B7: =IFERROR(INDIRECT("'Final Calculation Sheet'!$B"&INDEX('Buyer Lookup'!$A:$AZ,MATCH($B$2,'Buyer Lookup'!$A:$A,0),2)),"") -> SCRAP COPPER OF T/F WINDING (Oil impregnated paper insulated T/F winding) | C7: =IFERROR(INDIRECT("'Final Calculation Sheet'!$B"&INDEX('Buyer Lookup'!$A:$AZ,MATCH($B$2,'Buyer Lookup'!$A:$A,0),3)),"") -> 0 | D7: =IFERROR(INDIRECT("'Final Calculation Sheet'!$B"&INDEX('Buyer Lookup'!$A:$AZ,MATCH($B$2,'Buyer Lookup'!$A:$A,0),4)),"") | E7: =IFERROR(INDIRECT("'Final Calculation Sheet'!$B"&INDEX('Buyer Lookup'!$A:$AZ,MATCH($B$2,'Buyer Lookup'!$A:$A,0),5)),"") | F7: =IFERROR(INDIRECT("'Final Calculation Sheet'!$B"&INDEX('Buyer Lookup'!$A:$AZ,MATCH($B$2,'Buyer Lookup'!$A:$A,0),6)),"") | G7: =IFERROR(INDIRECT("'Final Calculation Sheet'!$B"&INDEX('Buyer Lookup'!$A:$AZ,MATCH($B$2,'Buyer Lookup'!$A:$A,0),7)),"") | H7: =IFERROR(INDIRECT("'Final Calculation Sheet'!$B"&INDEX('Buyer Lookup'!$A:$AZ,MATCH($B$2,'Buyer Lookup'!$A:$A,0),8)),"") | I7: =IFERROR(INDIRECT("'Final Calculation Sheet'!$B"&INDEX('Buyer Lookup'!$A:$AZ,MATCH($B$2,'Buyer Lookup'!$A:$A,0),9)),"") | J7: =IFERROR(INDIRECT("'Final Calculation Sheet'!$B"&INDEX('Buyer Lookup'!$A:$AZ,MATCH($B$2,'Buyer Lookup'!$A:$A,0),10)),"") | K7: =IFERROR(INDIRECT("'Final Calculation Sheet'!$B"&INDEX('Buyer Lookup'!$A:$AZ,MATCH($B$2,'Buyer Lookup'!$A:$A,0),11)),"") | L7: =IFERROR(INDIRECT("'Final Calculation Sheet'!$B"&INDEX('Buyer Lookup'!$A:$AZ,MATCH($B$2,'Buyer Lookup'!$A:$A,0),12)),"") | M7: =IFERROR(INDIRECT("'Final Calculation Sheet'!$B"&INDEX('Buyer Lookup'!$A:$AZ,MATCH($B$2,'Buyer Lookup'!$A:$A,0),13)),"") | N7: =IFERROR(INDIRECT("'Final Calculation Sheet'!$B"&INDEX('Buyer Lookup'!$A:$AZ,MATCH($B$2,'Buyer Lookup'!$A:$A,0),14)),"")
A8: Bid Sheet | B8: =IFERROR(INDIRECT("'Final Calculation Sheet'!$D"&INDEX('Buyer Lookup'!$A:$AZ,MATCH($B$2,'Buyer Lookup'!$A:$A,0),2)),"") -> 21980 | C8: =IFERROR(INDIRECT("'Final Calculation Sheet'!$D"&INDEX('Buyer Lookup'!$A:$AZ,MATCH($B$2,'Buyer Lookup'!$A:$A,0),3)),"") -> 0 | D8: =IFERROR(INDIRECT("'Final Calculation Sheet'!$D"&INDEX('Buyer Lookup'!$A:$AZ,MATCH($B$2,'Buyer Lookup'!$A:$A,0),4)),"") | E8: =IFERROR(INDIRECT("'Final Calculation Sheet'!$D"&INDEX('Buyer Lookup'!$A:$AZ,MATCH($B$2,'Buyer Lookup'!$A:$A,0),5)),"") | F8: =IFERROR(INDIRECT("'Final Calculation Sheet'!$D"&INDEX('Buyer Lookup'!$A:$AZ,MATCH($B$2,'Buyer Lookup'!$A:$A,0),6)),"") | G8: =IFERROR(INDIRECT("'Final Calculation Sheet'!$D"&INDEX('Buyer Lookup'!$A:$AZ,MATCH($B$2,'Buyer Lookup'!$A:$A,0),7)),"") | H8: =IFERROR(INDIRECT("'Final Calculation Sheet'!$D"&INDEX('Buyer Lookup'!$A:$AZ,MATCH($B$2,'Buyer Lookup'!$A:$A,0),8)),"") | I8: =IFERROR(INDIRECT("'Final Calculation Sheet'!$D"&INDEX('Buyer Lookup'!$A:$AZ,MATCH($B$2,'Buyer Lookup'!$A:$A,0),9)),"") | J8: =IFERROR(INDIRECT("'Final Calculation Sheet'!$D"&INDEX('Buyer Lookup'!$A:$AZ,MATCH($B$2,'Buyer Lookup'!$A:$A,0),10)),"") | K8: =IFERROR(INDIRECT("'Final Calculation Sheet'!$D"&INDEX('Buyer Lookup'!$A:$AZ,MATCH($B$2,'Buyer Lookup'!$A:$A,0),11)),"") | L8: =IFERROR(INDIRECT("'Final Calculation Sheet'!$D"&INDEX('Buyer Lookup'!$A:$AZ,MATCH($B$2,'Buyer Lookup'!$A:$A,0),12)),"") | M8: =IFERROR(INDIRECT("'Final Calculation Sheet'!$D"&INDEX('Buyer Lookup'!$A:$AZ,MATCH($B$2,'Buyer Lookup'!$A:$A,0),13)),"") | N8: =IFERROR(INDIRECT("'Final Calculation Sheet'!$D"&INDEX('Buyer Lookup'!$A:$AZ,MATCH($B$2,'Buyer Lookup'!$A:$A,0),14)),"")
A9: Quantity | B9: =IFERROR(INDIRECT("'Final Calculation Sheet'!$A"&INDEX('Buyer Lookup'!$A:$AZ,MATCH($B$2,'Buyer Lookup'!$A:$A,0),2)),"") -> 669 | C9: =IFERROR(INDIRECT("'Final Calculation Sheet'!$A"&INDEX('Buyer Lookup'!$A:$AZ,MATCH($B$2,'Buyer Lookup'!$A:$A,0),3)),"") -> 0 | D9: =IFERROR(INDIRECT("'Final Calculation Sheet'!$A"&INDEX('Buyer Lookup'!$A:$AZ,MATCH($B$2,'Buyer Lookup'!$A:$A,0),4)),"") | E9: =IFERROR(INDIRECT("'Final Calculation Sheet'!$A"&INDEX('Buyer Lookup'!$A:$AZ,MATCH($B$2,'Buyer Lookup'!$A:$A,0),5)),"") | F9: =IFERROR(INDIRECT("'Final Calculation Sheet'!$A"&INDEX('Buyer Lookup'!$A:$AZ,MATCH($B$2,'Buyer Lookup'!$A:$A,0),6)),"") | G9: =IFERROR(INDIRECT("'Final Calculation Sheet'!$A"&INDEX('Buyer Lookup'!$A:$AZ,MATCH($B$2,'Buyer Lookup'!$A:$A,0),7)),"") | H9: =IFERROR(INDIRECT("'Final Calculation Sheet'!$A"&INDEX('Buyer Lookup'!$A:$AZ,MATCH($B$2,'Buyer Lookup'!$A:$A,0),8)),"") | I9: =IFERROR(INDIRECT("'Final Calculation Sheet'!$A"&INDEX('Buyer Lookup'!$A:$AZ,MATCH($B$2,'Buyer Lookup'!$A:$A,0),9)),"") | J9: =IFERROR(INDIRECT("'Final Calculation Sheet'!$A"&INDEX('Buyer Lookup'!$A:$AZ,MATCH($B$2,'Buyer Lookup'!$A:$A,0),10)),"") | K9: =IFERROR(INDIRECT("'Final Calculation Sheet'!$A"&INDEX('Buyer Lookup'!$A:$AZ,MATCH($B$2,'Buyer Lookup'!$A:$A,0),11)),"") | L9: =IFERROR(INDIRECT("'Final Calculation Sheet'!$A"&INDEX('Buyer Lookup'!$A:$AZ,MATCH($B$2,'Buyer Lookup'!$A:$A,0),12)),"") | M9: =IFERROR(INDIRECT("'Final Calculation Sheet'!$A"&INDEX('Buyer Lookup'!$A:$AZ,MATCH($B$2,'Buyer Lookup'!$A:$A,0),13)),"") | N9: =IFERROR(INDIRECT("'Final Calculation Sheet'!$A"&INDEX('Buyer Lookup'!$A:$AZ,MATCH($B$2,'Buyer Lookup'!$A:$A,0),14)),"")
A10: Unit | B10: =IFERROR(INDIRECT("'Final Calculation Sheet'!$E"&INDEX('Buyer Lookup'!$A:$AZ,MATCH($B$2,'Buyer Lookup'!$A:$A,0),2)),"") -> KG | C10: =IFERROR(INDIRECT("'Final Calculation Sheet'!$E"&INDEX('Buyer Lookup'!$A:$AZ,MATCH($B$2,'Buyer Lookup'!$A:$A,0),3)),"") -> 0 | D10: =IFERROR(INDIRECT("'Final Calculation Sheet'!$E"&INDEX('Buyer Lookup'!$A:$AZ,MATCH($B$2,'Buyer Lookup'!$A:$A,0),4)),"") | E10: =IFERROR(INDIRECT("'Final Calculation Sheet'!$E"&INDEX('Buyer Lookup'!$A:$AZ,MATCH($B$2,'Buyer Lookup'!$A:$A,0),5)),"") | F10: =IFERROR(INDIRECT("'Final Calculation Sheet'!$E"&INDEX('Buyer Lookup'!$A:$AZ,MATCH($B$2,'Buyer Lookup'!$A:$A,0),6)),"") | G10: =IFERROR(INDIRECT("'Final Calculation Sheet'!$E"&INDEX('Buyer Lookup'!$A:$AZ,MATCH($B$2,'Buyer Lookup'!$A:$A,0),7)),"") | H10: =IFERROR(INDIRECT("'Final Calculation Sheet'!$E"&INDEX('Buyer Lookup'!$A:$AZ,MATCH($B$2,'Buyer Lookup'!$A:$A,0),8)),"") | I10: =IFERROR(INDIRECT("'Final Calculation Sheet'!$E"&INDEX('Buyer Lookup'!$A:$AZ,MATCH($B$2,'Buyer Lookup'!$A:$A,0),9)),"") | J10: =IFERROR(INDIRECT("'Final Calculation Sheet'!$E"&INDEX('Buyer Lookup'!$A:$AZ,MATCH($B$2,'Buyer Lookup'!$A:$A,0),10)),"") | K10: =IFERROR(INDIRECT("'Final Calculation Sheet'!$E"&INDEX('Buyer Lookup'!$A:$AZ,MATCH($B$2,'Buyer Lookup'!$A:$A,0),11)),"") | L10: =IFERROR(INDIRECT("'Final Calculation Sheet'!$E"&INDEX('Buyer Lookup'!$A:$AZ,MATCH($B$2,'Buyer Lookup'!$A:$A,0),12)),"") | M10: =IFERROR(INDIRECT("'Final Calculation Sheet'!$E"&INDEX('Buyer Lookup'!$A:$AZ,MATCH($B$2,'Buyer Lookup'!$A:$A,0),13)),"") | N10: =IFERROR(INDIRECT("'Final Calculation Sheet'!$E"&INDEX('Buyer Lookup'!$A:$AZ,MATCH($B$2,'Buyer Lookup'!$A:$A,0),14)),"")
A11: Rate (₹) | B11: =IFERROR(INDIRECT("'Final Calculation Sheet'!$C"&INDEX('Buyer Lookup'!$A:$AZ,MATCH($B$2,'Buyer Lookup'!$A:$A,0),2)),"") -> 1181 | C11: =IFERROR(INDIRECT("'Final Calculation Sheet'!$C"&INDEX('Buyer Lookup'!$A:$AZ,MATCH($B$2,'Buyer Lookup'!$A:$A,0),3)),"") -> 0 | D11: =IFERROR(INDIRECT("'Final Calculation Sheet'!$C"&INDEX('Buyer Lookup'!$A:$AZ,MATCH($B$2,'Buyer Lookup'!$A:$A,0),4)),"") | E11: =IFERROR(INDIRECT("'Final Calculation Sheet'!$C"&INDEX('Buyer Lookup'!$A:$AZ,MATCH($B$2,'Buyer Lookup'!$A:$A,0),5)),"") | F11: =IFERROR(INDIRECT("'Final Calculation Sheet'!$C"&INDEX('Buyer Lookup'!$A:$AZ,MATCH($B$2,'Buyer Lookup'!$A:$A,0),6)),"") | G11: =IFERROR(INDIRECT("'Final Calculation Sheet'!$C"&INDEX('Buyer Lookup'!$A:$AZ,MATCH($B$2,'Buyer Lookup'!$A:$A,0),7)),"") | H11: =IFERROR(INDIRECT("'Final Calculation Sheet'!$C"&INDEX('Buyer Lookup'!$A:$AZ,MATCH($B$2,'Buyer Lookup'!$A:$A,0),8)),"") | I11: =IFERROR(INDIRECT("'Final Calculation Sheet'!$C"&INDEX('Buyer Lookup'!$A:$AZ,MATCH($B$2,'Buyer Lookup'!$A:$A,0),9)),"") | J11: =IFERROR(INDIRECT("'Final Calculation Sheet'!$C"&INDEX('Buyer Lookup'!$A:$AZ,MATCH($B$2,'Buyer Lookup'!$A:$A,0),10)),"") | K11: =IFERROR(INDIRECT("'Final Calculation Sheet'!$C"&INDEX('Buyer Lookup'!$A:$AZ,MATCH($B$2,'Buyer Lookup'!$A:$A,0),11)),"") | L11: =IFERROR(INDIRECT("'Final Calculation Sheet'!$C"&INDEX('Buyer Lookup'!$A:$AZ,MATCH($B$2,'Buyer Lookup'!$A:$A,0),12)),"") | M11: =IFERROR(INDIRECT("'Final Calculation Sheet'!$C"&INDEX('Buyer Lookup'!$A:$AZ,MATCH($B$2,'Buyer Lookup'!$A:$A,0),13)),"") | N11: =IFERROR(INDIRECT("'Final Calculation Sheet'!$C"&INDEX('Buyer Lookup'!$A:$AZ,MATCH($B$2,'Buyer Lookup'!$A:$A,0),14)),"")
A13: FINANCIALS
A14: Mat. Value (₹) | B14: =IFERROR(INDIRECT("'Final Calculation Sheet'!$H"&INDEX('Buyer Lookup'!$A:$AZ,MATCH($B$2,'Buyer Lookup'!$A:$A,0),2)),"") -> 790089 | C14: =IFERROR(INDIRECT("'Final Calculation Sheet'!$H"&INDEX('Buyer Lookup'!$A:$AZ,MATCH($B$2,'Buyer Lookup'!$A:$A,0),3)),"") -> 0 | D14: =IFERROR(INDIRECT("'Final Calculation Sheet'!$H"&INDEX('Buyer Lookup'!$A:$AZ,MATCH($B$2,'Buyer Lookup'!$A:$A,0),4)),"") | E14: =IFERROR(INDIRECT("'Final Calculation Sheet'!$H"&INDEX('Buyer Lookup'!$A:$AZ,MATCH($B$2,'Buyer Lookup'!$A:$A,0),5)),"") | F14: =IFERROR(INDIRECT("'Final Calculation Sheet'!$H"&INDEX('Buyer Lookup'!$A:$AZ,MATCH($B$2,'Buyer Lookup'!$A:$A,0),6)),"") | G14: =IFERROR(INDIRECT("'Final Calculation Sheet'!$H"&INDEX('Buyer Lookup'!$A:$AZ,MATCH($B$2,'Buyer Lookup'!$A:$A,0),7)),"") | H14: =IFERROR(INDIRECT("'Final Calculation Sheet'!$H"&INDEX('Buyer Lookup'!$A:$AZ,MATCH($B$2,'Buyer Lookup'!$A:$A,0),8)),"") | I14: =IFERROR(INDIRECT("'Final Calculation Sheet'!$H"&INDEX('Buyer Lookup'!$A:$AZ,MATCH($B$2,'Buyer Lookup'!$A:$A,0),9)),"") | J14: =IFERROR(INDIRECT("'Final Calculation Sheet'!$H"&INDEX('Buyer Lookup'!$A:$AZ,MATCH($B$2,'Buyer Lookup'!$A:$A,0),10)),"") | K14: =IFERROR(INDIRECT("'Final Calculation Sheet'!$H"&INDEX('Buyer Lookup'!$A:$AZ,MATCH($B$2,'Buyer Lookup'!$A:$A,0),11)),"") | L14: =IFERROR(INDIRECT("'Final Calculation Sheet'!$H"&INDEX('Buyer Lookup'!$A:$AZ,MATCH($B$2,'Buyer Lookup'!$A:$A,0),12)),"") | M14: =IFERROR(INDIRECT("'Final Calculation Sheet'!$H"&INDEX('Buyer Lookup'!$A:$AZ,MATCH($B$2,'Buyer Lookup'!$A:$A,0),13)),"") | N14: =IFERROR(INDIRECT("'Final Calculation Sheet'!$H"&INDEX('Buyer Lookup'!$A:$AZ,MATCH($B$2,'Buyer Lookup'!$A:$A,0),14)),"")
A15: GST (₹) | B15: =IFERROR(INDIRECT("'Final Calculation Sheet'!$I"&INDEX('Buyer Lookup'!$A:$AZ,MATCH($B$2,'Buyer Lookup'!$A:$A,0),2)),"") -> 142216 | C15: =IFERROR(INDIRECT("'Final Calculation Sheet'!$I"&INDEX('Buyer Lookup'!$A:$AZ,MATCH($B$2,'Buyer Lookup'!$A:$A,0),3)),"") -> 0 | D15: =IFERROR(INDIRECT("'Final Calculation Sheet'!$I"&INDEX('Buyer Lookup'!$A:$AZ,MATCH($B$2,'Buyer Lookup'!$A:$A,0),4)),"") | E15: =IFERROR(INDIRECT("'Final Calculation Sheet'!$I"&INDEX('Buyer Lookup'!$A:$AZ,MATCH($B$2,'Buyer Lookup'!$A:$A,0),5)),"") | F15: =IFERROR(INDIRECT("'Final Calculation Sheet'!$I"&INDEX('Buyer Lookup'!$A:$AZ,MATCH($B$2,'Buyer Lookup'!$A:$A,0),6)),"") | G15: =IFERROR(INDIRECT("'Final Calculation Sheet'!$I"&INDEX('Buyer Lookup'!$A:$AZ,MATCH($B$2,'Buyer Lookup'!$A:$A,0),7)),"") | H15: =IFERROR(INDIRECT("'Final Calculation Sheet'!$I"&INDEX('Buyer Lookup'!$A:$AZ,MATCH($B$2,'Buyer Lookup'!$A:$A,0),8)),"") | I15: =IFERROR(INDIRECT("'Final Calculation Sheet'!$I"&INDEX('Buyer Lookup'!$A:$AZ,MATCH($B$2,'Buyer Lookup'!$A:$A,0),9)),"") | J15: =IFERROR(INDIRECT("'Final Calculation Sheet'!$I"&INDEX('Buyer Lookup'!$A:$AZ,MATCH($B$2,'Buyer Lookup'!$A:$A,0),10)),"") | K15: =IFERROR(INDIRECT("'Final Calculation Sheet'!$I"&INDEX('Buyer Lookup'!$A:$AZ,MATCH($B$2,'Buyer Lookup'!$A:$A,0),11)),"") | L15: =IFERROR(INDIRECT("'Final Calculation Sheet'!$I"&INDEX('Buyer Lookup'!$A:$AZ,MATCH($B$2,'Buyer Lookup'!$A:$A,0),12)),"") | M15: =IFERROR(INDIRECT("'Final Calculation Sheet'!$I"&INDEX('Buyer Lookup'!$A:$AZ,MATCH($B$2,'Buyer Lookup'!$A:$A,0),13)),"") | N15: =IFERROR(INDIRECT("'Final Calculation Sheet'!$I"&INDEX('Buyer Lookup'!$A:$AZ,MATCH($B$2,'Buyer Lookup'!$A:$A,0),14)),"")
A16: Mat. Value + GST (₹) | B16: =IFERROR(INDIRECT("'Final Calculation Sheet'!$J"&INDEX('Buyer Lookup'!$A:$AZ,MATCH($B$2,'Buyer Lookup'!$A:$A,0),2)),"") -> 932305 | C16: =IFERROR(INDIRECT("'Final Calculation Sheet'!$J"&INDEX('Buyer Lookup'!$A:$AZ,MATCH($B$2,'Buyer Lookup'!$A:$A,0),3)),"") -> 0 | D16: =IFERROR(INDIRECT("'Final Calculation Sheet'!$J"&INDEX('Buyer Lookup'!$A:$AZ,MATCH($B$2,'Buyer Lookup'!$A:$A,0),4)),"") | E16: =IFERROR(INDIRECT("'Final Calculation Sheet'!$J"&INDEX('Buyer Lookup'!$A:$AZ,MATCH($B$2,'Buyer Lookup'!$A:$A,0),5)),"") | F16: =IFERROR(INDIRECT("'Final Calculation Sheet'!$J"&INDEX('Buyer Lookup'!$A:$AZ,MATCH($B$2,'Buyer Lookup'!$A:$A,0),6)),"") | G16: =IFERROR(INDIRECT("'Final Calculation Sheet'!$J"&INDEX('Buyer Lookup'!$A:$AZ,MATCH($B$2,'Buyer Lookup'!$A:$A,0),7)),"") | H16: =IFERROR(INDIRECT("'Final Calculation Sheet'!$J"&INDEX('Buyer Lookup'!$A:$AZ,MATCH($B$2,'Buyer Lookup'!$A:$A,0),8)),"") | I16: =IFERROR(INDIRECT("'Final Calculation Sheet'!$J"&INDEX('Buyer Lookup'!$A:$AZ,MATCH($B$2,'Buyer Lookup'!$A:$A,0),9)),"") | J16: =IFERROR(INDIRECT("'Final Calculation Sheet'!$J"&INDEX('Buyer Lookup'!$A:$AZ,MATCH($B$2,'Buyer Lookup'!$A:$A,0),10)),"") | K16: =IFERROR(INDIRECT("'Final Calculation Sheet'!$J"&INDEX('Buyer Lookup'!$A:$AZ,MATCH($B$2,'Buyer Lookup'!$A:$A,0),11)),"") | L16: =IFERROR(INDIRECT("'Final Calculation Sheet'!$J"&INDEX('Buyer Lookup'!$A:$AZ,MATCH($B$2,'Buyer Lookup'!$A:$A,0),12)),"") | M16: =IFERROR(INDIRECT("'Final Calculation Sheet'!$J"&INDEX('Buyer Lookup'!$A:$AZ,MATCH($B$2,'Buyer Lookup'!$A:$A,0),13)),"") | N16: =IFERROR(INDIRECT("'Final Calculation Sheet'!$J"&INDEX('Buyer Lookup'!$A:$AZ,MATCH($B$2,'Buyer Lookup'!$A:$A,0),14)),"")
A17: TCS (₹) | B17: =IFERROR(INDIRECT("'Final Calculation Sheet'!$K"&INDEX('Buyer Lookup'!$A:$AZ,MATCH($B$2,'Buyer Lookup'!$A:$A,0),2)),"") -> 18646 | C17: =IFERROR(INDIRECT("'Final Calculation Sheet'!$K"&INDEX('Buyer Lookup'!$A:$AZ,MATCH($B$2,'Buyer Lookup'!$A:$A,0),3)),"") -> 0 | D17: =IFERROR(INDIRECT("'Final Calculation Sheet'!$K"&INDEX('Buyer Lookup'!$A:$AZ,MATCH($B$2,'Buyer Lookup'!$A:$A,0),4)),"") | E17: =IFERROR(INDIRECT("'Final Calculation Sheet'!$K"&INDEX('Buyer Lookup'!$A:$AZ,MATCH($B$2,'Buyer Lookup'!$A:$A,0),5)),"") | F17: =IFERROR(INDIRECT("'Final Calculation Sheet'!$K"&INDEX('Buyer Lookup'!$A:$AZ,MATCH($B$2,'Buyer Lookup'!$A:$A,0),6)),"") | G17: =IFERROR(INDIRECT("'Final Calculation Sheet'!$K"&INDEX('Buyer Lookup'!$A:$AZ,MATCH($B$2,'Buyer Lookup'!$A:$A,0),7)),"") | H17: =IFERROR(INDIRECT("'Final Calculation Sheet'!$K"&INDEX('Buyer Lookup'!$A:$AZ,MATCH($B$2,'Buyer Lookup'!$A:$A,0),8)),"") | I17: =IFERROR(INDIRECT("'Final Calculation Sheet'!$K"&INDEX('Buyer Lookup'!$A:$AZ,MATCH($B$2,'Buyer Lookup'!$A:$A,0),9)),"") | J17: =IFERROR(INDIRECT("'Final Calculation Sheet'!$K"&INDEX('Buyer Lookup'!$A:$AZ,MATCH($B$2,'Buyer Lookup'!$A:$A,0),10)),"") | K17: =IFERROR(INDIRECT("'Final Calculation Sheet'!$K"&INDEX('Buyer Lookup'!$A:$AZ,MATCH($B$2,'Buyer Lookup'!$A:$A,0),11)),"") | L17: =IFERROR(INDIRECT("'Final Calculation Sheet'!$K"&INDEX('Buyer Lookup'!$A:$AZ,MATCH($B$2,'Buyer Lookup'!$A:$A,0),12)),"") | M17: =IFERROR(INDIRECT("'Final Calculation Sheet'!$K"&INDEX('Buyer Lookup'!$A:$AZ,MATCH($B$2,'Buyer Lookup'!$A:$A,0),13)),"") | N17: =IFERROR(INDIRECT("'Final Calculation Sheet'!$K"&INDEX('Buyer Lookup'!$A:$AZ,MATCH($B$2,'Buyer Lookup'!$A:$A,0),14)),"")
A18: TDS u/s 194(O) (₹) | B18: =IFERROR(INDIRECT("'Final Calculation Sheet'!$L"&INDEX('Buyer Lookup'!$A:$AZ,MATCH($B$2,'Buyer Lookup'!$A:$A,0),2)),"") -> 790.089 | C18: =IFERROR(INDIRECT("'Final Calculation Sheet'!$L"&INDEX('Buyer Lookup'!$A:$AZ,MATCH($B$2,'Buyer Lookup'!$A:$A,0),3)),"") -> 0 | D18: =IFERROR(INDIRECT("'Final Calculation Sheet'!$L"&INDEX('Buyer Lookup'!$A:$AZ,MATCH($B$2,'Buyer Lookup'!$A:$A,0),4)),"") | E18: =IFERROR(INDIRECT("'Final Calculation Sheet'!$L"&INDEX('Buyer Lookup'!$A:$AZ,MATCH($B$2,'Buyer Lookup'!$A:$A,0),5)),"") | F18: =IFERROR(INDIRECT("'Final Calculation Sheet'!$L"&INDEX('Buyer Lookup'!$A:$AZ,MATCH($B$2,'Buyer Lookup'!$A:$A,0),6)),"") | G18: =IFERROR(INDIRECT("'Final Calculation Sheet'!$L"&INDEX('Buyer Lookup'!$A:$AZ,MATCH($B$2,'Buyer Lookup'!$A:$A,0),7)),"") | H18: =IFERROR(INDIRECT("'Final Calculation Sheet'!$L"&INDEX('Buyer Lookup'!$A:$AZ,MATCH($B$2,'Buyer Lookup'!$A:$A,0),8)),"") | I18: =IFERROR(INDIRECT("'Final Calculation Sheet'!$L"&INDEX('Buyer Lookup'!$A:$AZ,MATCH($B$2,'Buyer Lookup'!$A:$A,0),9)),"") | J18: =IFERROR(INDIRECT("'Final Calculation Sheet'!$L"&INDEX('Buyer Lookup'!$A:$AZ,MATCH($B$2,'Buyer Lookup'!$A:$A,0),10)),"") | K18: =IFERROR(INDIRECT("'Final Calculation Sheet'!$L"&INDEX('Buyer Lookup'!$A:$AZ,MATCH($B$2,'Buyer Lookup'!$A:$A,0),11)),"") | L18: =IFERROR(INDIRECT("'Final Calculation Sheet'!$L"&INDEX('Buyer Lookup'!$A:$AZ,MATCH($B$2,'Buyer Lookup'!$A:$A,0),12)),"") | M18: =IFERROR(INDIRECT("'Final Calculation Sheet'!$L"&INDEX('Buyer Lookup'!$A:$AZ,MATCH($B$2,'Buyer Lookup'!$A:$A,0),13)),"") | N18: =IFERROR(INDIRECT("'Final Calculation Sheet'!$L"&INDEX('Buyer Lookup'!$A:$AZ,MATCH($B$2,'Buyer Lookup'!$A:$A,0),14)),"")
A19: Service Charge (₹) | B19: =IFERROR(INDIRECT("'Final Calculation Sheet'!$M"&INDEX('Buyer Lookup'!$A:$AZ,MATCH($B$2,'Buyer Lookup'!$A:$A,0),2)),"") -> 20976.863 | C19: =IFERROR(INDIRECT("'Final Calculation Sheet'!$M"&INDEX('Buyer Lookup'!$A:$AZ,MATCH($B$2,'Buyer Lookup'!$A:$A,0),3)),"") -> 0 | D19: =IFERROR(INDIRECT("'Final Calculation Sheet'!$M"&INDEX('Buyer Lookup'!$A:$AZ,MATCH($B$2,'Buyer Lookup'!$A:$A,0),4)),"") | E19: =IFERROR(INDIRECT("'Final Calculation Sheet'!$M"&INDEX('Buyer Lookup'!$A:$AZ,MATCH($B$2,'Buyer Lookup'!$A:$A,0),5)),"") | F19: =IFERROR(INDIRECT("'Final Calculation Sheet'!$M"&INDEX('Buyer Lookup'!$A:$AZ,MATCH($B$2,'Buyer Lookup'!$A:$A,0),6)),"") | G19: =IFERROR(INDIRECT("'Final Calculation Sheet'!$M"&INDEX('Buyer Lookup'!$A:$AZ,MATCH($B$2,'Buyer Lookup'!$A:$A,0),7)),"") | H19: =IFERROR(INDIRECT("'Final Calculation Sheet'!$M"&INDEX('Buyer Lookup'!$A:$AZ,MATCH($B$2,'Buyer Lookup'!$A:$A,0),8)),"") | I19: =IFERROR(INDIRECT("'Final Calculation Sheet'!$M"&INDEX('Buyer Lookup'!$A:$AZ,MATCH($B$2,'Buyer Lookup'!$A:$A,0),9)),"") | J19: =IFERROR(INDIRECT("'Final Calculation Sheet'!$M"&INDEX('Buyer Lookup'!$A:$AZ,MATCH($B$2,'Buyer Lookup'!$A:$A,0),10)),"") | K19: =IFERROR(INDIRECT("'Final Calculation Sheet'!$M"&INDEX('Buyer Lookup'!$A:$AZ,MATCH($B$2,'Buyer Lookup'!$A:$A,0),11)),"") | L19: =IFERROR(INDIRECT("'Final Calculation Sheet'!$M"&INDEX('Buyer Lookup'!$A:$AZ,MATCH($B$2,'Buyer Lookup'!$A:$A,0),12)),"") | M19: =IFERROR(INDIRECT("'Final Calculation Sheet'!$M"&INDEX('Buyer Lookup'!$A:$AZ,MATCH($B$2,'Buyer Lookup'!$A:$A,0),13)),"") | N19: =IFERROR(INDIRECT("'Final Calculation Sheet'!$M"&INDEX('Buyer Lookup'!$A:$AZ,MATCH($B$2,'Buyer Lookup'!$A:$A,0),14)),"")
A20: TDS u/s 194(H) (₹) | B20: =IFERROR(INDIRECT("'Final Calculation Sheet'!$N"&INDEX('Buyer Lookup'!$A:$AZ,MATCH($B$2,'Buyer Lookup'!$A:$A,0),2)),"") -> 355.54005 | C20: =IFERROR(INDIRECT("'Final Calculation Sheet'!$N"&INDEX('Buyer Lookup'!$A:$AZ,MATCH($B$2,'Buyer Lookup'!$A:$A,0),3)),"") -> 0 | D20: =IFERROR(INDIRECT("'Final Calculation Sheet'!$N"&INDEX('Buyer Lookup'!$A:$AZ,MATCH($B$2,'Buyer Lookup'!$A:$A,0),4)),"") | E20: =IFERROR(INDIRECT("'Final Calculation Sheet'!$N"&INDEX('Buyer Lookup'!$A:$AZ,MATCH($B$2,'Buyer Lookup'!$A:$A,0),5)),"") | F20: =IFERROR(INDIRECT("'Final Calculation Sheet'!$N"&INDEX('Buyer Lookup'!$A:$AZ,MATCH($B$2,'Buyer Lookup'!$A:$A,0),6)),"") | G20: =IFERROR(INDIRECT("'Final Calculation Sheet'!$N"&INDEX('Buyer Lookup'!$A:$AZ,MATCH($B$2,'Buyer Lookup'!$A:$A,0),7)),"") | H20: =IFERROR(INDIRECT("'Final Calculation Sheet'!$N"&INDEX('Buyer Lookup'!$A:$AZ,MATCH($B$2,'Buyer Lookup'!$A:$A,0),8)),"") | I20: =IFERROR(INDIRECT("'Final Calculation Sheet'!$N"&INDEX('Buyer Lookup'!$A:$AZ,MATCH($B$2,'Buyer Lookup'!$A:$A,0),9)),"") | J20: =IFERROR(INDIRECT("'Final Calculation Sheet'!$N"&INDEX('Buyer Lookup'!$A:$AZ,MATCH($B$2,'Buyer Lookup'!$A:$A,0),10)),"") | K20: =IFERROR(INDIRECT("'Final Calculation Sheet'!$N"&INDEX('Buyer Lookup'!$A:$AZ,MATCH($B$2,'Buyer Lookup'!$A:$A,0),11)),"") | L20: =IFERROR(INDIRECT("'Final Calculation Sheet'!$N"&INDEX('Buyer Lookup'!$A:$AZ,MATCH($B$2,'Buyer Lookup'!$A:$A,0),12)),"") | M20: =IFERROR(INDIRECT("'Final Calculation Sheet'!$N"&INDEX('Buyer Lookup'!$A:$AZ,MATCH($B$2,'Buyer Lookup'!$A:$A,0),13)),"") | N20: =IFERROR(INDIRECT("'Final Calculation Sheet'!$N"&INDEX('Buyer Lookup'!$A:$AZ,MATCH($B$2,'Buyer Lookup'!$A:$A,0),14)),"")
A21: Net Svc Charge (₹) | B21: =IFERROR(INDIRECT("'Final Calculation Sheet'!$O"&INDEX('Buyer Lookup'!$A:$AZ,MATCH($B$2,'Buyer Lookup'!$A:$A,0),2)),"") -> 20621.323 | C21: =IFERROR(INDIRECT("'Final Calculation Sheet'!$O"&INDEX('Buyer Lookup'!$A:$AZ,MATCH($B$2,'Buyer Lookup'!$A:$A,0),3)),"") -> 0 | D21: =IFERROR(INDIRECT("'Final Calculation Sheet'!$O"&INDEX('Buyer Lookup'!$A:$AZ,MATCH($B$2,'Buyer Lookup'!$A:$A,0),4)),"") | E21: =IFERROR(INDIRECT("'Final Calculation Sheet'!$O"&INDEX('Buyer Lookup'!$A:$AZ,MATCH($B$2,'Buyer Lookup'!$A:$A,0),5)),"") | F21: =IFERROR(INDIRECT("'Final Calculation Sheet'!$O"&INDEX('Buyer Lookup'!$A:$AZ,MATCH($B$2,'Buyer Lookup'!$A:$A,0),6)),"") | G21: =IFERROR(INDIRECT("'Final Calculation Sheet'!$O"&INDEX('Buyer Lookup'!$A:$AZ,MATCH($B$2,'Buyer Lookup'!$A:$A,0),7)),"") | H21: =IFERROR(INDIRECT("'Final Calculation Sheet'!$O"&INDEX('Buyer Lookup'!$A:$AZ,MATCH($B$2,'Buyer Lookup'!$A:$A,0),8)),"") | I21: =IFERROR(INDIRECT("'Final Calculation Sheet'!$O"&INDEX('Buyer Lookup'!$A:$AZ,MATCH($B$2,'Buyer Lookup'!$A:$A,0),9)),"") | J21: =IFERROR(INDIRECT("'Final Calculation Sheet'!$O"&INDEX('Buyer Lookup'!$A:$AZ,MATCH($B$2,'Buyer Lookup'!$A:$A,0),10)),"") | K21: =IFERROR(INDIRECT("'Final Calculation Sheet'!$O"&INDEX('Buyer Lookup'!$A:$AZ,MATCH($B$2,'Buyer Lookup'!$A:$A,0),11)),"") | L21: =IFERROR(INDIRECT("'Final Calculation Sheet'!$O"&INDEX('Buyer Lookup'!$A:$AZ,MATCH($B$2,'Buyer Lookup'!$A:$A,0),12)),"") | M21: =IFERROR(INDIRECT("'Final Calculation Sheet'!$O"&INDEX('Buyer Lookup'!$A:$AZ,MATCH($B$2,'Buyer Lookup'!$A:$A,0),13)),"") | N21: =IFERROR(INDIRECT("'Final Calculation Sheet'!$O"&INDEX('Buyer Lookup'!$A:$AZ,MATCH($B$2,'Buyer Lookup'!$A:$A,0),14)),"")
A22: Svc Charge to MSTC (₹) | B22: =IFERROR(INDIRECT("'Final Calculation Sheet'!$P"&INDEX('Buyer Lookup'!$A:$AZ,MATCH($B$2,'Buyer Lookup'!$A:$A,0),2)),"") -> 21411 | C22: =IFERROR(INDIRECT("'Final Calculation Sheet'!$P"&INDEX('Buyer Lookup'!$A:$AZ,MATCH($B$2,'Buyer Lookup'!$A:$A,0),3)),"") -> 0 | D22: =IFERROR(INDIRECT("'Final Calculation Sheet'!$P"&INDEX('Buyer Lookup'!$A:$AZ,MATCH($B$2,'Buyer Lookup'!$A:$A,0),4)),"") | E22: =IFERROR(INDIRECT("'Final Calculation Sheet'!$P"&INDEX('Buyer Lookup'!$A:$AZ,MATCH($B$2,'Buyer Lookup'!$A:$A,0),5)),"") | F22: =IFERROR(INDIRECT("'Final Calculation Sheet'!$P"&INDEX('Buyer Lookup'!$A:$AZ,MATCH($B$2,'Buyer Lookup'!$A:$A,0),6)),"") | G22: =IFERROR(INDIRECT("'Final Calculation Sheet'!$P"&INDEX('Buyer Lookup'!$A:$AZ,MATCH($B$2,'Buyer Lookup'!$A:$A,0),7)),"") | H22: =IFERROR(INDIRECT("'Final Calculation Sheet'!$P"&INDEX('Buyer Lookup'!$A:$AZ,MATCH($B$2,'Buyer Lookup'!$A:$A,0),8)),"") | I22: =IFERROR(INDIRECT("'Final Calculation Sheet'!$P"&INDEX('Buyer Lookup'!$A:$AZ,MATCH($B$2,'Buyer Lookup'!$A:$A,0),9)),"") | J22: =IFERROR(INDIRECT("'Final Calculation Sheet'!$P"&INDEX('Buyer Lookup'!$A:$AZ,MATCH($B$2,'Buyer Lookup'!$A:$A,0),10)),"") | K22: =IFERROR(INDIRECT("'Final Calculation Sheet'!$P"&INDEX('Buyer Lookup'!$A:$AZ,MATCH($B$2,'Buyer Lookup'!$A:$A,0),11)),"") | L22: =IFERROR(INDIRECT("'Final Calculation Sheet'!$P"&INDEX('Buyer Lookup'!$A:$AZ,MATCH($B$2,'Buyer Lookup'!$A:$A,0),12)),"") | M22: =IFERROR(INDIRECT("'Final Calculation Sheet'!$P"&INDEX('Buyer Lookup'!$A:$AZ,MATCH($B$2,'Buyer Lookup'!$A:$A,0),13)),"") | N22: =IFERROR(INDIRECT("'Final Calculation Sheet'!$P"&INDEX('Buyer Lookup'!$A:$AZ,MATCH($B$2,'Buyer Lookup'!$A:$A,0),14)),"")
A23: GST TDS Rate | B23: =IFERROR(INDIRECT("'Final Calculation Sheet'!$Q"&INDEX('Buyer Lookup'!$A:$AZ,MATCH($B$2,'Buyer Lookup'!$A:$A,0),2)),"") -> 0.02 | C23: =IFERROR(INDIRECT("'Final Calculation Sheet'!$Q"&INDEX('Buyer Lookup'!$A:$AZ,MATCH($B$2,'Buyer Lookup'!$A:$A,0),3)),"") -> 0 | D23: =IFERROR(INDIRECT("'Final Calculation Sheet'!$Q"&INDEX('Buyer Lookup'!$A:$AZ,MATCH($B$2,'Buyer Lookup'!$A:$A,0),4)),"") | E23: =IFERROR(INDIRECT("'Final Calculation Sheet'!$Q"&INDEX('Buyer Lookup'!$A:$AZ,MATCH($B$2,'Buyer Lookup'!$A:$A,0),5)),"") | F23: =IFERROR(INDIRECT("'Final Calculation Sheet'!$Q"&INDEX('Buyer Lookup'!$A:$AZ,MATCH($B$2,'Buyer Lookup'!$A:$A,0),6)),"") | G23: =IFERROR(INDIRECT("'Final Calculation Sheet'!$Q"&INDEX('Buyer Lookup'!$A:$AZ,MATCH($B$2,'Buyer Lookup'!$A:$A,0),7)),"") | H23: =IFERROR(INDIRECT("'Final Calculation Sheet'!$Q"&INDEX('Buyer Lookup'!$A:$AZ,MATCH($B$2,'Buyer Lookup'!$A:$A,0),8)),"") | I23: =IFERROR(INDIRECT("'Final Calculation Sheet'!$Q"&INDEX('Buyer Lookup'!$A:$AZ,MATCH($B$2,'Buyer Lookup'!$A:$A,0),9)),"") | J23: =IFERROR(INDIRECT("'Final Calculation Sheet'!$Q"&INDEX('Buyer Lookup'!$A:$AZ,MATCH($B$2,'Buyer Lookup'!$A:$A,0),10)),"") | K23: =IFERROR(INDIRECT("'Final Calculation Sheet'!$Q"&INDEX('Buyer Lookup'!$A:$AZ,MATCH($B$2,'Buyer Lookup'!$A:$A,0),11)),"") | L23: =IFERROR(INDIRECT("'Final Calculation Sheet'!$Q"&INDEX('Buyer Lookup'!$A:$AZ,MATCH($B$2,'Buyer Lookup'!$A:$A,0),12)),"") | M23: =IFERROR(INDIRECT("'Final Calculation Sheet'!$Q"&INDEX('Buyer Lookup'!$A:$AZ,MATCH($B$2,'Buyer Lookup'!$A:$A,0),13)),"") | N23: =IFERROR(INDIRECT("'Final Calculation Sheet'!$Q"&INDEX('Buyer Lookup'!$A:$AZ,MATCH($B$2,'Buyer Lookup'!$A:$A,0),14)),"")
A24: GST TDS (₹) | B24: =IFERROR(INDIRECT("'Final Calculation Sheet'!$R"&INDEX('Buyer Lookup'!$A:$AZ,MATCH($B$2,'Buyer Lookup'!$A:$A,0),2)),"") -> 15802 | C24: =IFERROR(INDIRECT("'Final Calculation Sheet'!$R"&INDEX('Buyer Lookup'!$A:$AZ,MATCH($B$2,'Buyer Lookup'!$A:$A,0),3)),"") -> 0 | D24: =IFERROR(INDIRECT("'Final Calculation Sheet'!$R"&INDEX('Buyer Lookup'!$A:$AZ,MATCH($B$2,'Buyer Lookup'!$A:$A,0),4)),"") | E24: =IFERROR(INDIRECT("'Final Calculation Sheet'!$R"&INDEX('Buyer Lookup'!$A:$AZ,MATCH($B$2,'Buyer Lookup'!$A:$A,0),5)),"") | F24: =IFERROR(INDIRECT("'Final Calculation Sheet'!$R"&INDEX('Buyer Lookup'!$A:$AZ,MATCH($B$2,'Buyer Lookup'!$A:$A,0),6)),"") | G24: =IFERROR(INDIRECT("'Final Calculation Sheet'!$R"&INDEX('Buyer Lookup'!$A:$AZ,MATCH($B$2,'Buyer Lookup'!$A:$A,0),7)),"") | H24: =IFERROR(INDIRECT("'Final Calculation Sheet'!$R"&INDEX('Buyer Lookup'!$A:$AZ,MATCH($B$2,'Buyer Lookup'!$A:$A,0),8)),"") | I24: =IFERROR(INDIRECT("'Final Calculation Sheet'!$R"&INDEX('Buyer Lookup'!$A:$AZ,MATCH($B$2,'Buyer Lookup'!$A:$A,0),9)),"") | J24: =IFERROR(INDIRECT("'Final Calculation Sheet'!$R"&INDEX('Buyer Lookup'!$A:$AZ,MATCH($B$2,'Buyer Lookup'!$A:$A,0),10)),"") | K24: =IFERROR(INDIRECT("'Final Calculation Sheet'!$R"&INDEX('Buyer Lookup'!$A:$AZ,MATCH($B$2,'Buyer Lookup'!$A:$A,0),11)),"") | L24: =IFERROR(INDIRECT("'Final Calculation Sheet'!$R"&INDEX('Buyer Lookup'!$A:$AZ,MATCH($B$2,'Buyer Lookup'!$A:$A,0),12)),"") | M24: =IFERROR(INDIRECT("'Final Calculation Sheet'!$R"&INDEX('Buyer Lookup'!$A:$AZ,MATCH($B$2,'Buyer Lookup'!$A:$A,0),13)),"") | N24: =IFERROR(INDIRECT("'Final Calculation Sheet'!$R"&INDEX('Buyer Lookup'!$A:$AZ,MATCH($B$2,'Buyer Lookup'!$A:$A,0),14)),"")
A25: Total Receivables (₹) | B25: =IFERROR(INDIRECT("'Final Calculation Sheet'!$S"&INDEX('Buyer Lookup'!$A:$AZ,MATCH($B$2,'Buyer Lookup'!$A:$A,0),2)),"") -> 913738 | C25: =IFERROR(INDIRECT("'Final Calculation Sheet'!$S"&INDEX('Buyer Lookup'!$A:$AZ,MATCH($B$2,'Buyer Lookup'!$A:$A,0),3)),"") -> 0 | D25: =IFERROR(INDIRECT("'Final Calculation Sheet'!$S"&INDEX('Buyer Lookup'!$A:$AZ,MATCH($B$2,'Buyer Lookup'!$A:$A,0),4)),"") | E25: =IFERROR(INDIRECT("'Final Calculation Sheet'!$S"&INDEX('Buyer Lookup'!$A:$AZ,MATCH($B$2,'Buyer Lookup'!$A:$A,0),5)),"") | F25: =IFERROR(INDIRECT("'Final Calculation Sheet'!$S"&INDEX('Buyer Lookup'!$A:$AZ,MATCH($B$2,'Buyer Lookup'!$A:$A,0),6)),"") | G25: =IFERROR(INDIRECT("'Final Calculation Sheet'!$S"&INDEX('Buyer Lookup'!$A:$AZ,MATCH($B$2,'Buyer Lookup'!$A:$A,0),7)),"") | H25: =IFERROR(INDIRECT("'Final Calculation Sheet'!$S"&INDEX('Buyer Lookup'!$A:$AZ,MATCH($B$2,'Buyer Lookup'!$A:$A,0),8)),"") | I25: =IFERROR(INDIRECT("'Final Calculation Sheet'!$S"&INDEX('Buyer Lookup'!$A:$AZ,MATCH($B$2,'Buyer Lookup'!$A:$A,0),9)),"") | J25: =IFERROR(INDIRECT("'Final Calculation Sheet'!$S"&INDEX('Buyer Lookup'!$A:$AZ,MATCH($B$2,'Buyer Lookup'!$A:$A,0),10)),"") | K25: =IFERROR(INDIRECT("'Final Calculation Sheet'!$S"&INDEX('Buyer Lookup'!$A:$AZ,MATCH($B$2,'Buyer Lookup'!$A:$A,0),11)),"") | L25: =IFERROR(INDIRECT("'Final Calculation Sheet'!$S"&INDEX('Buyer Lookup'!$A:$AZ,MATCH($B$2,'Buyer Lookup'!$A:$A,0),12)),"") | M25: =IFERROR(INDIRECT("'Final Calculation Sheet'!$S"&INDEX('Buyer Lookup'!$A:$AZ,MATCH($B$2,'Buyer Lookup'!$A:$A,0),13)),"") | N25: =IFERROR(INDIRECT("'Final Calculation Sheet'!$S"&INDEX('Buyer Lookup'!$A:$AZ,MATCH($B$2,'Buyer Lookup'!$A:$A,0),14)),"")
A27: SECURITY DEPOSIT
A28: SD Expected (₹) | B28: =IFERROR(INDIRECT("'Final Calculation Sheet'!$T"&INDEX('Buyer Lookup'!$A:$AZ,MATCH($B$2,'Buyer Lookup'!$A:$A,0),2)),"") -> 197522 | C28: =IFERROR(INDIRECT("'Final Calculation Sheet'!$T"&INDEX('Buyer Lookup'!$A:$AZ,MATCH($B$2,'Buyer Lookup'!$A:$A,0),3)),"") -> 0 | D28: =IFERROR(INDIRECT("'Final Calculation Sheet'!$T"&INDEX('Buyer Lookup'!$A:$AZ,MATCH($B$2,'Buyer Lookup'!$A:$A,0),4)),"") | E28: =IFERROR(INDIRECT("'Final Calculation Sheet'!$T"&INDEX('Buyer Lookup'!$A:$AZ,MATCH($B$2,'Buyer Lookup'!$A:$A,0),5)),"") | F28: =IFERROR(INDIRECT("'Final Calculation Sheet'!$T"&INDEX('Buyer Lookup'!$A:$AZ,MATCH($B$2,'Buyer Lookup'!$A:$A,0),6)),"") | G28: =IFERROR(INDIRECT("'Final Calculation Sheet'!$T"&INDEX('Buyer Lookup'!$A:$AZ,MATCH($B$2,'Buyer Lookup'!$A:$A,0),7)),"") | H28: =IFERROR(INDIRECT("'Final Calculation Sheet'!$T"&INDEX('Buyer Lookup'!$A:$AZ,MATCH($B$2,'Buyer Lookup'!$A:$A,0),8)),"") | I28: =IFERROR(INDIRECT("'Final Calculation Sheet'!$T"&INDEX('Buyer Lookup'!$A:$AZ,MATCH($B$2,'Buyer Lookup'!$A:$A,0),9)),"") | J28: =IFERROR(INDIRECT("'Final Calculation Sheet'!$T"&INDEX('Buyer Lookup'!$A:$AZ,MATCH($B$2,'Buyer Lookup'!$A:$A,0),10)),"") | K28: =IFERROR(INDIRECT("'Final Calculation Sheet'!$T"&INDEX('Buyer Lookup'!$A:$AZ,MATCH($B$2,'Buyer Lookup'!$A:$A,0),11)),"") | L28: =IFERROR(INDIRECT("'Final Calculation Sheet'!$T"&INDEX('Buyer Lookup'!$A:$AZ,MATCH($B$2,'Buyer Lookup'!$A:$A,0),12)),"") | M28: =IFERROR(INDIRECT("'Final Calculation Sheet'!$T"&INDEX('Buyer Lookup'!$A:$AZ,MATCH($B$2,'Buyer Lookup'!$A:$A,0),13)),"") | N28: =IFERROR(INDIRECT("'Final Calculation Sheet'!$T"&INDEX('Buyer Lookup'!$A:$AZ,MATCH($B$2,'Buyer Lookup'!$A:$A,0),14)),"")
A29: SD Received (₹) | B29: =IFERROR(INDIRECT("'Final Calculation Sheet'!$U"&INDEX('Buyer Lookup'!$A:$AZ,MATCH($B$2,'Buyer Lookup'!$A:$A,0),2)),"") -> 197522 | C29: =IFERROR(INDIRECT("'Final Calculation Sheet'!$U"&INDEX('Buyer Lookup'!$A:$AZ,MATCH($B$2,'Buyer Lookup'!$A:$A,0),3)),"") -> 0 | D29: =IFERROR(INDIRECT("'Final Calculation Sheet'!$U"&INDEX('Buyer Lookup'!$A:$AZ,MATCH($B$2,'Buyer Lookup'!$A:$A,0),4)),"") | E29: =IFERROR(INDIRECT("'Final Calculation Sheet'!$U"&INDEX('Buyer Lookup'!$A:$AZ,MATCH($B$2,'Buyer Lookup'!$A:$A,0),5)),"") | F29: =IFERROR(INDIRECT("'Final Calculation Sheet'!$U"&INDEX('Buyer Lookup'!$A:$AZ,MATCH($B$2,'Buyer Lookup'!$A:$A,0),6)),"") | G29: =IFERROR(INDIRECT("'Final Calculation Sheet'!$U"&INDEX('Buyer Lookup'!$A:$AZ,MATCH($B$2,'Buyer Lookup'!$A:$A,0),7)),"") | H29: =IFERROR(INDIRECT("'Final Calculation Sheet'!$U"&INDEX('Buyer Lookup'!$A:$AZ,MATCH($B$2,'Buyer Lookup'!$A:$A,0),8)),"") | I29: =IFERROR(INDIRECT("'Final Calculation Sheet'!$U"&INDEX('Buyer Lookup'!$A:$AZ,MATCH($B$2,'Buyer Lookup'!$A:$A,0),9)),"") | J29: =IFERROR(INDIRECT("'Final Calculation Sheet'!$U"&INDEX('Buyer Lookup'!$A:$AZ,MATCH($B$2,'Buyer Lookup'!$A:$A,0),10)),"") | K29: =IFERROR(INDIRECT("'Final Calculation Sheet'!$U"&INDEX('Buyer Lookup'!$A:$AZ,MATCH($B$2,'Buyer Lookup'!$A:$A,0),11)),"") | L29: =IFERROR(INDIRECT("'Final Calculation Sheet'!$U"&INDEX('Buyer Lookup'!$A:$AZ,MATCH($B$2,'Buyer Lookup'!$A:$A,0),12)),"") | M29: =IFERROR(INDIRECT("'Final Calculation Sheet'!$U"&INDEX('Buyer Lookup'!$A:$AZ,MATCH($B$2,'Buyer Lookup'!$A:$A,0),13)),"") | N29: =IFERROR(INDIRECT("'Final Calculation Sheet'!$U"&INDEX('Buyer Lookup'!$A:$AZ,MATCH($B$2,'Buyer Lookup'!$A:$A,0),14)),"")
A30: SD Receipt Date | B30: =IFERROR(INDIRECT("'Final Calculation Sheet'!$V"&INDEX('Buyer Lookup'!$A:$AZ,MATCH($B$2,'Buyer Lookup'!$A:$A,0),2)),"") -> 24.08.2026 | C30: =IFERROR(INDIRECT("'Final Calculation Sheet'!$V"&INDEX('Buyer Lookup'!$A:$AZ,MATCH($B$2,'Buyer Lookup'!$A:$A,0),3)),"") -> 0 | D30: =IFERROR(INDIRECT("'Final Calculation Sheet'!$V"&INDEX('Buyer Lookup'!$A:$AZ,MATCH($B$2,'Buyer Lookup'!$A:$A,0),4)),"") | E30: =IFERROR(INDIRECT("'Final Calculation Sheet'!$V"&INDEX('Buyer Lookup'!$A:$AZ,MATCH($B$2,'Buyer Lookup'!$A:$A,0),5)),"") | F30: =IFERROR(INDIRECT("'Final Calculation Sheet'!$V"&INDEX('Buyer Lookup'!$A:$AZ,MATCH($B$2,'Buyer Lookup'!$A:$A,0),6)),"") | G30: =IFERROR(INDIRECT("'Final Calculation Sheet'!$V"&INDEX('Buyer Lookup'!$A:$AZ,MATCH($B$2,'Buyer Lookup'!$A:$A,0),7)),"") | H30: =IFERROR(INDIRECT("'Final Calculation Sheet'!$V"&INDEX('Buyer Lookup'!$A:$AZ,MATCH($B$2,'Buyer Lookup'!$A:$A,0),8)),"") | I30: =IFERROR(INDIRECT("'Final Calculation Sheet'!$V"&INDEX('Buyer Lookup'!$A:$AZ,MATCH($B$2,'Buyer Lookup'!$A:$A,0),9)),"") | J30: =IFERROR(INDIRECT("'Final Calculation Sheet'!$V"&INDEX('Buyer Lookup'!$A:$AZ,MATCH($B$2,'Buyer Lookup'!$A:$A,0),10)),"") | K30: =IFERROR(INDIRECT("'Final Calculation Sheet'!$V"&INDEX('Buyer Lookup'!$A:$AZ,MATCH($B$2,'Buyer Lookup'!$A:$A,0),11)),"") | L30: =IFERROR(INDIRECT("'Final Calculation Sheet'!$V"&INDEX('Buyer Lookup'!$A:$AZ,MATCH($B$2,'Buyer Lookup'!$A:$A,0),12)),"") | M30: =IFERROR(INDIRECT("'Final Calculation Sheet'!$V"&INDEX('Buyer Lookup'!$A:$AZ,MATCH($B$2,'Buyer Lookup'!$A:$A,0),13)),"") | N30: =IFERROR(INDIRECT("'Final Calculation Sheet'!$V"&INDEX('Buyer Lookup'!$A:$AZ,MATCH($B$2,'Buyer Lookup'!$A:$A,0),14)),"")
A32: FINAL PAYMENT
A33: FP Expected (₹) | B33: =IFERROR(INDIRECT("'Final Calculation Sheet'!$W"&INDEX('Buyer Lookup'!$A:$AZ,MATCH($B$2,'Buyer Lookup'!$A:$A,0),2)),"") -> 716215 | C33: =IFERROR(INDIRECT("'Final Calculation Sheet'!$W"&INDEX('Buyer Lookup'!$A:$AZ,MATCH($B$2,'Buyer Lookup'!$A:$A,0),3)),"") -> 0 | D33: =IFERROR(INDIRECT("'Final Calculation Sheet'!$W"&INDEX('Buyer Lookup'!$A:$AZ,MATCH($B$2,'Buyer Lookup'!$A:$A,0),4)),"") | E33: =IFERROR(INDIRECT("'Final Calculation Sheet'!$W"&INDEX('Buyer Lookup'!$A:$AZ,MATCH($B$2,'Buyer Lookup'!$A:$A,0),5)),"") | F33: =IFERROR(INDIRECT("'Final Calculation Sheet'!$W"&INDEX('Buyer Lookup'!$A:$AZ,MATCH($B$2,'Buyer Lookup'!$A:$A,0),6)),"") | G33: =IFERROR(INDIRECT("'Final Calculation Sheet'!$W"&INDEX('Buyer Lookup'!$A:$AZ,MATCH($B$2,'Buyer Lookup'!$A:$A,0),7)),"") | H33: =IFERROR(INDIRECT("'Final Calculation Sheet'!$W"&INDEX('Buyer Lookup'!$A:$AZ,MATCH($B$2,'Buyer Lookup'!$A:$A,0),8)),"") | I33: =IFERROR(INDIRECT("'Final Calculation Sheet'!$W"&INDEX('Buyer Lookup'!$A:$AZ,MATCH($B$2,'Buyer Lookup'!$A:$A,0),9)),"") | J33: =IFERROR(INDIRECT("'Final Calculation Sheet'!$W"&INDEX('Buyer Lookup'!$A:$AZ,MATCH($B$2,'Buyer Lookup'!$A:$A,0),10)),"") | K33: =IFERROR(INDIRECT("'Final Calculation Sheet'!$W"&INDEX('Buyer Lookup'!$A:$AZ,MATCH($B$2,'Buyer Lookup'!$A:$A,0),11)),"") | L33: =IFERROR(INDIRECT("'Final Calculation Sheet'!$W"&INDEX('Buyer Lookup'!$A:$AZ,MATCH($B$2,'Buyer Lookup'!$A:$A,0),12)),"") | M33: =IFERROR(INDIRECT("'Final Calculation Sheet'!$W"&INDEX('Buyer Lookup'!$A:$AZ,MATCH($B$2,'Buyer Lookup'!$A:$A,0),13)),"") | N33: =IFERROR(INDIRECT("'Final Calculation Sheet'!$W"&INDEX('Buyer Lookup'!$A:$AZ,MATCH($B$2,'Buyer Lookup'!$A:$A,0),14)),"")
A34: FP Received (₹) | B34: =IFERROR(INDIRECT("'Final Calculation Sheet'!$X"&INDEX('Buyer Lookup'!$A:$AZ,MATCH($B$2,'Buyer Lookup'!$A:$A,0),2)),"") -> 716216 | C34: =IFERROR(INDIRECT("'Final Calculation Sheet'!$X"&INDEX('Buyer Lookup'!$A:$AZ,MATCH($B$2,'Buyer Lookup'!$A:$A,0),3)),"") -> 0 | D34: =IFERROR(INDIRECT("'Final Calculation Sheet'!$X"&INDEX('Buyer Lookup'!$A:$AZ,MATCH($B$2,'Buyer Lookup'!$A:$A,0),4)),"") | E34: =IFERROR(INDIRECT("'Final Calculation Sheet'!$X"&INDEX('Buyer Lookup'!$A:$AZ,MATCH($B$2,'Buyer Lookup'!$A:$A,0),5)),"") | F34: =IFERROR(INDIRECT("'Final Calculation Sheet'!$X"&INDEX('Buyer Lookup'!$A:$AZ,MATCH($B$2,'Buyer Lookup'!$A:$A,0),6)),"") | G34: =IFERROR(INDIRECT("'Final Calculation Sheet'!$X"&INDEX('Buyer Lookup'!$A:$AZ,MATCH($B$2,'Buyer Lookup'!$A:$A,0),7)),"") | H34: =IFERROR(INDIRECT("'Final Calculation Sheet'!$X"&INDEX('Buyer Lookup'!$A:$AZ,MATCH($B$2,'Buyer Lookup'!$A:$A,0),8)),"") | I34: =IFERROR(INDIRECT("'Final Calculation Sheet'!$X"&INDEX('Buyer Lookup'!$A:$AZ,MATCH($B$2,'Buyer Lookup'!$A:$A,0),9)),"") | J34: =IFERROR(INDIRECT("'Final Calculation Sheet'!$X"&INDEX('Buyer Lookup'!$A:$AZ,MATCH($B$2,'Buyer Lookup'!$A:$A,0),10)),"") | K34: =IFERROR(INDIRECT("'Final Calculation Sheet'!$X"&INDEX('Buyer Lookup'!$A:$AZ,MATCH($B$2,'Buyer Lookup'!$A:$A,0),11)),"") | L34: =IFERROR(INDIRECT("'Final Calculation Sheet'!$X"&INDEX('Buyer Lookup'!$A:$AZ,MATCH($B$2,'Buyer Lookup'!$A:$A,0),12)),"") | M34: =IFERROR(INDIRECT("'Final Calculation Sheet'!$X"&INDEX('Buyer Lookup'!$A:$AZ,MATCH($B$2,'Buyer Lookup'!$A:$A,0),13)),"") | N34: =IFERROR(INDIRECT("'Final Calculation Sheet'!$X"&INDEX('Buyer Lookup'!$A:$AZ,MATCH($B$2,'Buyer Lookup'!$A:$A,0),14)),"")
A35: FP Receipt Date | B35: =IFERROR(INDIRECT("'Final Calculation Sheet'!$Y"&INDEX('Buyer Lookup'!$A:$AZ,MATCH($B$2,'Buyer Lookup'!$A:$A,0),2)),"") -> 18.08.2026 | C35: =IFERROR(INDIRECT("'Final Calculation Sheet'!$Y"&INDEX('Buyer Lookup'!$A:$AZ,MATCH($B$2,'Buyer Lookup'!$A:$A,0),3)),"") -> 0 | D35: =IFERROR(INDIRECT("'Final Calculation Sheet'!$Y"&INDEX('Buyer Lookup'!$A:$AZ,MATCH($B$2,'Buyer Lookup'!$A:$A,0),4)),"") | E35: =IFERROR(INDIRECT("'Final Calculation Sheet'!$Y"&INDEX('Buyer Lookup'!$A:$AZ,MATCH($B$2,'Buyer Lookup'!$A:$A,0),5)),"") | F35: =IFERROR(INDIRECT("'Final Calculation Sheet'!$Y"&INDEX('Buyer Lookup'!$A:$AZ,MATCH($B$2,'Buyer Lookup'!$A:$A,0),6)),"") | G35: =IFERROR(INDIRECT("'Final Calculation Sheet'!$Y"&INDEX('Buyer Lookup'!$A:$AZ,MATCH($B$2,'Buyer Lookup'!$A:$A,0),7)),"") | H35: =IFERROR(INDIRECT("'Final Calculation Sheet'!$Y"&INDEX('Buyer Lookup'!$A:$AZ,MATCH($B$2,'Buyer Lookup'!$A:$A,0),8)),"") | I35: =IFERROR(INDIRECT("'Final Calculation Sheet'!$Y"&INDEX('Buyer Lookup'!$A:$AZ,MATCH($B$2,'Buyer Lookup'!$A:$A,0),9)),"") | J35: =IFERROR(INDIRECT("'Final Calculation Sheet'!$Y"&INDEX('Buyer Lookup'!$A:$AZ,MATCH($B$2,'Buyer Lookup'!$A:$A,0),10)),"") | K35: =IFERROR(INDIRECT("'Final Calculation Sheet'!$Y"&INDEX('Buyer Lookup'!$A:$AZ,MATCH($B$2,'Buyer Lookup'!$A:$A,0),11)),"") | L35: =IFERROR(INDIRECT("'Final Calculation Sheet'!$Y"&INDEX('Buyer Lookup'!$A:$AZ,MATCH($B$2,'Buyer Lookup'!$A:$A,0),12)),"") | M35: =IFERROR(INDIRECT("'Final Calculation Sheet'!$Y"&INDEX('Buyer Lookup'!$A:$AZ,MATCH($B$2,'Buyer Lookup'!$A:$A,0),13)),"") | N35: =IFERROR(INDIRECT("'Final Calculation Sheet'!$Y"&INDEX('Buyer Lookup'!$A:$AZ,MATCH($B$2,'Buyer Lookup'!$A:$A,0),14)),"")
A37: LPP
A38: LPP Expected (₹) | B38: =IFERROR(INDIRECT("'Final Calculation Sheet'!$Z"&INDEX('Buyer Lookup'!$A:$AZ,MATCH($B$2,'Buyer Lookup'!$A:$A,0),2)),"") -> 0 | C38: =IFERROR(INDIRECT("'Final Calculation Sheet'!$Z"&INDEX('Buyer Lookup'!$A:$AZ,MATCH($B$2,'Buyer Lookup'!$A:$A,0),3)),"") -> 0 | D38: =IFERROR(INDIRECT("'Final Calculation Sheet'!$Z"&INDEX('Buyer Lookup'!$A:$AZ,MATCH($B$2,'Buyer Lookup'!$A:$A,0),4)),"") | E38: =IFERROR(INDIRECT("'Final Calculation Sheet'!$Z"&INDEX('Buyer Lookup'!$A:$AZ,MATCH($B$2,'Buyer Lookup'!$A:$A,0),5)),"") | F38: =IFERROR(INDIRECT("'Final Calculation Sheet'!$Z"&INDEX('Buyer Lookup'!$A:$AZ,MATCH($B$2,'Buyer Lookup'!$A:$A,0),6)),"") | G38: =IFERROR(INDIRECT("'Final Calculation Sheet'!$Z"&INDEX('Buyer Lookup'!$A:$AZ,MATCH($B$2,'Buyer Lookup'!$A:$A,0),7)),"") | H38: =IFERROR(INDIRECT("'Final Calculation Sheet'!$Z"&INDEX('Buyer Lookup'!$A:$AZ,MATCH($B$2,'Buyer Lookup'!$A:$A,0),8)),"") | I38: =IFERROR(INDIRECT("'Final Calculation Sheet'!$Z"&INDEX('Buyer Lookup'!$A:$AZ,MATCH($B$2,'Buyer Lookup'!$A:$A,0),9)),"") | J38: =IFERROR(INDIRECT("'Final Calculation Sheet'!$Z"&INDEX('Buyer Lookup'!$A:$AZ,MATCH($B$2,'Buyer Lookup'!$A:$A,0),10)),"") | K38: =IFERROR(INDIRECT("'Final Calculation Sheet'!$Z"&INDEX('Buyer Lookup'!$A:$AZ,MATCH($B$2,'Buyer Lookup'!$A:$A,0),11)),"") | L38: =IFERROR(INDIRECT("'Final Calculation Sheet'!$Z"&INDEX('Buyer Lookup'!$A:$AZ,MATCH($B$2,'Buyer Lookup'!$A:$A,0),12)),"") | M38: =IFERROR(INDIRECT("'Final Calculation Sheet'!$Z"&INDEX('Buyer Lookup'!$A:$AZ,MATCH($B$2,'Buyer Lookup'!$A:$A,0),13)),"") | N38: =IFERROR(INDIRECT("'Final Calculation Sheet'!$Z"&INDEX('Buyer Lookup'!$A:$AZ,MATCH($B$2,'Buyer Lookup'!$A:$A,0),14)),"")
A39: LPP Received (₹) | B39: =IFERROR(INDIRECT("'Final Calculation Sheet'!$AA"&INDEX('Buyer Lookup'!$A:$AZ,MATCH($B$2,'Buyer Lookup'!$A:$A,0),2)),"") -> 0 | C39: =IFERROR(INDIRECT("'Final Calculation Sheet'!$AA"&INDEX('Buyer Lookup'!$A:$AZ,MATCH($B$2,'Buyer Lookup'!$A:$A,0),3)),"") -> 0 | D39: =IFERROR(INDIRECT("'Final Calculation Sheet'!$AA"&INDEX('Buyer Lookup'!$A:$AZ,MATCH($B$2,'Buyer Lookup'!$A:$A,0),4)),"") | E39: =IFERROR(INDIRECT("'Final Calculation Sheet'!$AA"&INDEX('Buyer Lookup'!$A:$AZ,MATCH($B$2,'Buyer Lookup'!$A:$A,0),5)),"") | F39: =IFERROR(INDIRECT("'Final Calculation Sheet'!$AA"&INDEX('Buyer Lookup'!$A:$AZ,MATCH($B$2,'Buyer Lookup'!$A:$A,0),6)),"") | G39: =IFERROR(INDIRECT("'Final Calculation Sheet'!$AA"&INDEX('Buyer Lookup'!$A:$AZ,MATCH($B$2,'Buyer Lookup'!$A:$A,0),7)),"") | H39: =IFERROR(INDIRECT("'Final Calculation Sheet'!$AA"&INDEX('Buyer Lookup'!$A:$AZ,MATCH($B$2,'Buyer Lookup'!$A:$A,0),8)),"") | I39: =IFERROR(INDIRECT("'Final Calculation Sheet'!$AA"&INDEX('Buyer Lookup'!$A:$AZ,MATCH($B$2,'Buyer Lookup'!$A:$A,0),9)),"") | J39: =IFERROR(INDIRECT("'Final Calculation Sheet'!$AA"&INDEX('Buyer Lookup'!$A:$AZ,MATCH($B$2,'Buyer Lookup'!$A:$A,0),10)),"") | K39: =IFERROR(INDIRECT("'Final Calculation Sheet'!$AA"&INDEX('Buyer Lookup'!$A:$AZ,MATCH($B$2,'Buyer Lookup'!$A:$A,0),11)),"") | L39: =IFERROR(INDIRECT("'Final Calculation Sheet'!$AA"&INDEX('Buyer Lookup'!$A:$AZ,MATCH($B$2,'Buyer Lookup'!$A:$A,0),12)),"") | M39: =IFERROR(INDIRECT("'Final Calculation Sheet'!$AA"&INDEX('Buyer Lookup'!$A:$AZ,MATCH($B$2,'Buyer Lookup'!$A:$A,0),13)),"") | N39: =IFERROR(INDIRECT("'Final Calculation Sheet'!$AA"&INDEX('Buyer Lookup'!$A:$AZ,MATCH($B$2,'Buyer Lookup'!$A:$A,0),14)),"")
A40: LPP Receipt Date | B40: =IFERROR(INDIRECT("'Final Calculation Sheet'!$AB"&INDEX('Buyer Lookup'!$A:$AZ,MATCH($B$2,'Buyer Lookup'!$A:$A,0),2)),"") -> 0 | C40: =IFERROR(INDIRECT("'Final Calculation Sheet'!$AB"&INDEX('Buyer Lookup'!$A:$AZ,MATCH($B$2,'Buyer Lookup'!$A:$A,0),3)),"") -> 0 | D40: =IFERROR(INDIRECT("'Final Calculation Sheet'!$AB"&INDEX('Buyer Lookup'!$A:$AZ,MATCH($B$2,'Buyer Lookup'!$A:$A,0),4)),"") | E40: =IFERROR(INDIRECT("'Final Calculation Sheet'!$AB"&INDEX('Buyer Lookup'!$A:$AZ,MATCH($B$2,'Buyer Lookup'!$A:$A,0),5)),"") | F40: =IFERROR(INDIRECT("'Final Calculation Sheet'!$AB"&INDEX('Buyer Lookup'!$A:$AZ,MATCH($B$2,'Buyer Lookup'!$A:$A,0),6)),"") | G40: =IFERROR(INDIRECT("'Final Calculation Sheet'!$AB"&INDEX('Buyer Lookup'!$A:$AZ,MATCH($B$2,'Buyer Lookup'!$A:$A,0),7)),"") | H40: =IFERROR(INDIRECT("'Final Calculation Sheet'!$AB"&INDEX('Buyer Lookup'!$A:$AZ,MATCH($B$2,'Buyer Lookup'!$A:$A,0),8)),"") | I40: =IFERROR(INDIRECT("'Final Calculation Sheet'!$AB"&INDEX('Buyer Lookup'!$A:$AZ,MATCH($B$2,'Buyer Lookup'!$A:$A,0),9)),"") | J40: =IFERROR(INDIRECT("'Final Calculation Sheet'!$AB"&INDEX('Buyer Lookup'!$A:$AZ,MATCH($B$2,'Buyer Lookup'!$A:$A,0),10)),"") | K40: =IFERROR(INDIRECT("'Final Calculation Sheet'!$AB"&INDEX('Buyer Lookup'!$A:$AZ,MATCH($B$2,'Buyer Lookup'!$A:$A,0),11)),"") | L40: =IFERROR(INDIRECT("'Final Calculation Sheet'!$AB"&INDEX('Buyer Lookup'!$A:$AZ,MATCH($B$2,'Buyer Lookup'!$A:$A,0),12)),"") | M40: =IFERROR(INDIRECT("'Final Calculation Sheet'!$AB"&INDEX('Buyer Lookup'!$A:$AZ,MATCH($B$2,'Buyer Lookup'!$A:$A,0),13)),"") | N40: =IFERROR(INDIRECT("'Final Calculation Sheet'!$AB"&INDEX('Buyer Lookup'!$A:$AZ,MATCH($B$2,'Buyer Lookup'!$A:$A,0),14)),"")
A42: SUMMARY
A43: Total Received (₹) | B43: =IFERROR(INDIRECT("'Final Calculation Sheet'!$AC"&INDEX('Buyer Lookup'!$A:$AZ,MATCH($B$2,'Buyer Lookup'!$A:$A,0),2)),"") -> 0 | C43: =IFERROR(INDIRECT("'Final Calculation Sheet'!$AC"&INDEX('Buyer Lookup'!$A:$AZ,MATCH($B$2,'Buyer Lookup'!$A:$A,0),3)),"") -> 0 | D43: =IFERROR(INDIRECT("'Final Calculation Sheet'!$AC"&INDEX('Buyer Lookup'!$A:$AZ,MATCH($B$2,'Buyer Lookup'!$A:$A,0),4)),"") | E43: =IFERROR(INDIRECT("'Final Calculation Sheet'!$AC"&INDEX('Buyer Lookup'!$A:$AZ,MATCH($B$2,'Buyer Lookup'!$A:$A,0),5)),"") | F43: =IFERROR(INDIRECT("'Final Calculation Sheet'!$AC"&INDEX('Buyer Lookup'!$A:$AZ,MATCH($B$2,'Buyer Lookup'!$A:$A,0),6)),"") | G43: =IFERROR(INDIRECT("'Final Calculation Sheet'!$AC"&INDEX('Buyer Lookup'!$A:$AZ,MATCH($B$2,'Buyer Lookup'!$A:$A,0),7)),"") | H43: =IFERROR(INDIRECT("'Final Calculation Sheet'!$AC"&INDEX('Buyer Lookup'!$A:$AZ,MATCH($B$2,'Buyer Lookup'!$A:$A,0),8)),"") | I43: =IFERROR(INDIRECT("'Final Calculation Sheet'!$AC"&INDEX('Buyer Lookup'!$A:$AZ,MATCH($B$2,'Buyer Lookup'!$A:$A,0),9)),"") | J43: =IFERROR(INDIRECT("'Final Calculation Sheet'!$AC"&INDEX('Buyer Lookup'!$A:$AZ,MATCH($B$2,'Buyer Lookup'!$A:$A,0),10)),"") | K43: =IFERROR(INDIRECT("'Final Calculation Sheet'!$AC"&INDEX('Buyer Lookup'!$A:$AZ,MATCH($B$2,'Buyer Lookup'!$A:$A,0),11)),"") | L43: =IFERROR(INDIRECT("'Final Calculation Sheet'!$AC"&INDEX('Buyer Lookup'!$A:$AZ,MATCH($B$2,'Buyer Lookup'!$A:$A,0),12)),"") | M43: =IFERROR(INDIRECT("'Final Calculation Sheet'!$AC"&INDEX('Buyer Lookup'!$A:$AZ,MATCH($B$2,'Buyer Lookup'!$A:$A,0),13)),"") | N43: =IFERROR(INDIRECT("'Final Calculation Sheet'!$AC"&INDEX('Buyer Lookup'!$A:$AZ,MATCH($B$2,'Buyer Lookup'!$A:$A,0),14)),"")
A44: Outstanding (₹) | B44: =IFERROR(INDIRECT("'Final Calculation Sheet'!$AD"&INDEX('Buyer Lookup'!$A:$AZ,MATCH($B$2,'Buyer Lookup'!$A:$A,0),2)),"") -> 0 | C44: =IFERROR(INDIRECT("'Final Calculation Sheet'!$AD"&INDEX('Buyer Lookup'!$A:$AZ,MATCH($B$2,'Buyer Lookup'!$A:$A,0),3)),"") -> 0 | D44: =IFERROR(INDIRECT("'Final Calculation Sheet'!$AD"&INDEX('Buyer Lookup'!$A:$AZ,MATCH($B$2,'Buyer Lookup'!$A:$A,0),4)),"") | E44: =IFERROR(INDIRECT("'Final Calculation Sheet'!$AD"&INDEX('Buyer Lookup'!$A:$AZ,MATCH($B$2,'Buyer Lookup'!$A:$A,0),5)),"") | F44: =IFERROR(INDIRECT("'Final Calculation Sheet'!$AD"&INDEX('Buyer Lookup'!$A:$AZ,MATCH($B$2,'Buyer Lookup'!$A:$A,0),6)),"") | G44: =IFERROR(INDIRECT("'Final Calculation Sheet'!$AD"&INDEX('Buyer Lookup'!$A:$AZ,MATCH($B$2,'Buyer Lookup'!$A:$A,0),7)),"") | H44: =IFERROR(INDIRECT("'Final Calculation Sheet'!$AD"&INDEX('Buyer Lookup'!$A:$AZ,MATCH($B$2,'Buyer Lookup'!$A:$A,0),8)),"") | I44: =IFERROR(INDIRECT("'Final Calculation Sheet'!$AD"&INDEX('Buyer Lookup'!$A:$AZ,MATCH($B$2,'Buyer Lookup'!$A:$A,0),9)),"") | J44: =IFERROR(INDIRECT("'Final Calculation Sheet'!$AD"&INDEX('Buyer Lookup'!$A:$AZ,MATCH($B$2,'Buyer Lookup'!$A:$A,0),10)),"") | K44: =IFERROR(INDIRECT("'Final Calculation Sheet'!$AD"&INDEX('Buyer Lookup'!$A:$AZ,MATCH($B$2,'Buyer Lookup'!$A:$A,0),11)),"") | L44: =IFERROR(INDIRECT("'Final Calculation Sheet'!$AD"&INDEX('Buyer Lookup'!$A:$AZ,MATCH($B$2,'Buyer Lookup'!$A:$A,0),12)),"") | M44: =IFERROR(INDIRECT("'Final Calculation Sheet'!$AD"&INDEX('Buyer Lookup'!$A:$AZ,MATCH($B$2,'Buyer Lookup'!$A:$A,0),13)),"") | N44: =IFERROR(INDIRECT("'Final Calculation Sheet'!$AD"&INDEX('Buyer Lookup'!$A:$AZ,MATCH($B$2,'Buyer Lookup'!$A:$A,0),14)),"")
A46: DOCUMENT
...

Sheet Collapsible View
A1: MSTC LIMITED — Buyer-wise Collapsible Detail Sheet
A2: ► Use the row group controls on the LEFT MARGIN ( − / + buttons ) to collapse/expand each section within a buyer block
A3: Field / Buyer | B3: Lot 1 | C3: Lot 2 | D3: Lot 3 | E3: Lot 4 | F3: Lot 5 | G3: Lot 6 | H3: Lot 7 | I3: Lot 8 | J3: Lot 9 | K3: Lot 10 | L3: Lot 11 | M3: Lot 12 | N3: Lot 13 | O3: BUYER TOTAL
A4: AL HAMD TRADE CORPORATION (1 lot)
A5: Lot No. → | B5: 1763 | O5: Total
A6: ▸ LOT INFO
A7: Lot No. | B7: 1763
A8: Lot Name | B8: SCRAP COPPER OF T/F WINDING (Oil impregnated paper insulated T/F winding)
A9: Bid Sheet | B9: 21980
A10: Quantity | B10: 669
A11: Unit | B11: KG
A12: Rate (₹) | B12: 1181
A13: ▸ FINANCIALS
A14: Mat. Value (₹) | B14: 790089 | O14: =B14 -> 790089
A15: GST (₹) | B15: 142216 | O15: =B15 -> 142216
A16: Mat. Value + GST (₹) | B16: 932305 | O16: =B16 -> 932305
A17: TCS (₹) | B17: 18646 | O17: =B17 -> 18646
A18: TDS u/s 194(O) (₹) | B18: 790.089 | O18: =B18 -> 790.089
A19: Service Charge (₹) | B19: 20976.863 | O19: =B19 -> 20976.863
A20: TDS u/s 194(H) (₹) | B20: 355.54005 | O20: =B20 -> 355.54005
A21: Net Svc Charge (₹) | B21: 20621.323 | O21: =B21 -> 20621.323
A22: Svc Charge to MSTC (₹) | B22: 21411 | O22: =B22 -> 21411
A23: GST TDS Rate | B23: 0.02
A24: GST TDS (₹) | B24: 15802 | O24: =B24 -> 15802
A25: Total Receivables (₹) | B25: 913738 | O25: =B25 -> 913738
A26: ▸ SECURITY DEPOSIT
A27: SD Expected (₹) | B27: 197522 | O27: =B27 -> 197522
A28: SD Received (₹) | B28: 197522 | O28: =B28 -> 197522
A29: SD Receipt Date | B29: 24.08.2026
A30: ▸ FINAL PAYMENT
A31: FP Expected (₹) | B31: 716215 | O31: =B31 -> 716215
A32: FP Received (₹) | B32: 716216 | O32: =B32 -> 716216
A33: FP Receipt Date | B33: 18.08.2026
A34: ▸ LPP
A35: LPP Expected (₹) | B35: 0 | O35: =B35 -> 0
A36: LPP Received (₹) | O36: =B36 -> 0
A37: LPP Receipt Date
A38: ▸ SUMMARY
A39: Total Received (₹) | O39: =B39 -> 0
A40: Outstanding (₹) | B40: 0 | O40: =B40 -> 0
...

Sheet Final Calculation Sheet
B1: MSTC LIMITED - COMBINED BID SHEET (Auctions 21977, 21978, 21979, 21980)
A2: Filter by Buyer ▼ | B2: (All Buyers) | F2: Filter by Lot No. ▼ | G2: (All Lots) | I2: ① Pick Buyer or Lot No. from dropdown ② Click the ▼ AutoFilter arrow in Row 3 to filter ③ Clear: select "(All Buyers)" / "(All Lots)"
A3: Quantity | B3: Lot Name | C3: Rate | D3: Bid Sheet | E3: Unit | F3: Lot No. | G3: Buyer | H3: Mat. Value | I3: GST | J3: Mat. Value + GST | K3: TCS | L3: TDS u/s 194(O) | M3: Service Charge to MSTC | N3: TDS u/s 194(H) | O3: Net Service Charge (post TDS 194H) | P3: Service charge to MSTC | Q3: GST TDS Rate | R3: GST TDS | S3: Total Receivables in Cash | T3: Security Deposit (Expected) | U3: Security Deposit (Received) | V3: Date of Receipt | W3: Final Payment (Expected) | X3: Final Payment (Received) | Y3: Date of Receipt | Z3: LPP Expected | AA3: LPP Received | AB3: Date of Recepit of LPP | AC3: Total Received | AD3: Outstanding | AE3: Invoice No. | AF3: SAP Document | AG3: Doc./Invoice Date
A4: 669 | B4: SCRAP COPPER OF T/F WINDING (Oil impregnated paper insulated T/F winding) | C4: 1181 | D4: 21980 | E4: KG | F4: 1763 | G4: AL HAMD TRADE CORPORATION | H4: 790089 | I4: 142216 | J4: 932305 | K4: 18646 | L4: 790.089 | M4: 20976.863 | N4: 355.54005 | O4: 20621.323 | P4: 21411 | Q4: 0.02 | R4: 15802 | S4: 913738 | T4: 197522 | U4: 197522 | V4: 24.08.2026 | W4: 716215 | X4: 716216 | Y4: 18.08.2026 | Z4: 0 | AD4: 0 | AE4: DR2640100029 | AF4: 1800003271 | AG4: 24.08.2026
A5: 270 | B5: Scrap of Empty oil drum | C5: 580 | D5: 21977 | E5: NO | F5: 1874 | G5: NATIONAL ENTERPRISES | H5: 156600 | I5: 28188 | J5: 184788 | K5: 3696 | L5: 156.6 | M5: 4157.73 | N5: 70.47 | O5: 4087.26 | P5: 4244 | Q5: 0 | R5: 0 | S5: 184240 | T5: 39150 | U5: 39150 | V5: 13.08.2026 | W5: 145090 | X5: 145090 | Y5: 24.08.2026 | Z5: 0 | AD5: 0 | AE5: DR2640100030 | AF5: 1800003302 | AG5: 27.08.2026
A6: 28 | B6: Scrap of Copper of faulty AC compressor | C6: 1456 | D6: 21977 | E6: KG | F6: 1875 | G6: F R KHANS ENTERPRISES | H6: 40768 | I6: 7338 | J6: 48106 | K6: 962 | L6: 40.768 | M6: 1082.3904 | N6: 18.3456 | O6: 1064.0448 | P6: 1105 | Q6: 0 | R6: 0 | S6: 47964 | T6: 10192 | U6: 10192 | V6: 11.08.2026 | W6: 37772 | X6: 37772 | Y6: 20.08.2026 | Z6: 0 | AD6: 0 | AE6: DR2640100047 | AF6: 1800003346 | AG6: 27.08.2026
A7: 3000 | B7: Scrap of MS (extracted from equip cage and empty Sf6 gas cylinder) | C7: 66 | D7: 21977 | E7: KG | F7: 1876 | G7: F R KHANS ENTERPRISES | H7: 198000 | I7: 35640 | J7: 233640 | K7: 4673 | L7: 198 | M7: 5256.9 | N7: 89.1 | O7: 5167.8 | P7: 5366 | Q7: 0 | R7: 0 | S7: 232947 | T7: 49500 | U7: 49500 | V7: 11.08.2026 | W7: 183447 | X7: 183446 | Y7: 20.08.2026 | Z7: 0 | AD7: 1 | AE7: DR2640100048 | AF7: 1800003347 | AG7: 27.08.2026
A8: 7253 | B8: SCRAP ACSR CONDUCTORS (Conductor Pieces) | C8: 227 | D8: 21980 | E8: KG | F8: 1923 | G8: OMKAR STEELS | H8: 1646431 | I8: 296358 | J8: 1942789 | K8: 38856 | L8: 1646.431 | M8: 43712.743 | N8: 740.89395 | O8: 42971.849 | P8: 44618 | Q8: 0.02 | R8: 32929 | S8: 1904097 | T8: 411608 | U8: 411608 | V8: 14.08.2026 | W8: 1492489 | X8: 1492490 | Y8: 24.08.2026 | Z8: 0 | AD8: -1 | AE8: DR2640100045 | AF8: 1800003315 | AG8: 27.08.2026
A9: 1 | B9: Scrap Power Transformer | C9: 2787314 | D9: 21977 | E9: NO | F9: 1976 | G9: SHAR JAHAN TRADERS | H9: 2787314 | I9: 501717 | J9: 3289031 | K9: 65781 | L9: 2787.314 | M9: 74003.187 | N9: 1254.2913 | O9: 72748.895 | P9: 75536 | Q9: 0 | R9: 0 | S9: 3279275 | T9: 696829 | U9: 696829 | V9: 13.08.2026 | W9: 2582446 | X9: 2582447.1 | Y9: 13.08.2026 | Z9: 0 | AD9: -1.0942916 | AE9: DR2640100023 | AF9: 1800003194 | AG9: 17.08.2026
A10: 4 | B10: Scrap of 132 KV CT | C10: 51511 | D10: 21977 | E10: NO | F10: 2002 | G10: NATIONAL ENTERPRISES | H10: 206044 | I10: 37088 | J10: 243132 | K10: 4863 | L10: 206.044 | M10: 5470.4682 | N10: 92.7198 | O10: 5377.7484 | P10: 5584 | Q10: 0 | R10: 0 | S10: 242411 | T10: 51511 | U10: 51511 | V10: 13.08.2026 | W10: 190900 | X10: 190900 | Y10: 24.08.2026 | Z10: 0 | AD10: 0 | AE10: DR2640100031 | AF10: 1800003303 | AG10: 27.08.2026
A11: 1 | B11: Scrap of 145 KV CB | C11: 65007 | D11: 21977 | E11: NO | F11: 2003 | G11: NATIONAL ENTERPRISES | H11: 65007 | I11: 11701 | J11: 76708 | K11: 1534 | L11: 65.007 | M11: 1725.9359 | N11: 29.25315 | O11: 1696.6827 | P11: 1762 | Q11: 0 | R11: 0 | S11: 76481 | T11: 16252 | U11: 16252 | V11: 13.08.2026 | W11: 60229 | X11: 60229 | Y11: 24.08.2026 | Z11: 0 | AD11: 0 | AE11: DR2640100032 | AF11: 1800003304 | AG11: 27.08.2026
A12: 1 | B12: Scrap of 220KV CT | C12: 70006 | D12: 21977 | E12: NO | F12: 2005 | G12: NATIONAL ENTERPRISES | H12: 70006 | I12: 12601 | J12: 82607 | K12: 1652 | L12: 70.006 | M12: 1858.6593 | N12: 31.5027 | O12: 1827.1566 | P12: 1897 | Q12: 0 | R12: 0 | S12: 82362 | T12: 17502 | U12: 17502 | V12: 13.08.2026 | W12: 64861 | X12: 64859 | Y12: 24.08.2026 | Z12: 0 | AD12: 1 | AE12: DR2640100033 | AF12: 1800003305 | AG12: 27.08.2026
A13: 25 | B13: Scrap of empty oil drums | C13: 700 | D13: 21977 | E13: NO | F13: 2006 | G13: STERLING ENTERPRISES | H13: 17500 | I13: 3150 | J13: 20650 | K13: 413 | L13: 17.5 | M13: 464.625 | N13: 7.875 | O13: 456.75 | P13: 474 | Q13: 0 | R13: 0 | S13: 20589 | T13: 4375 | U13: 4375 | V13: 11.08.2026 | W13: 16214 | X13: 16214 | Y13: 11.08.2026 | Z13: 0 | AD13: 0 | AE13: DR2640100018 | AF13: 1800003156 | AG13: 14.08.2026
A14: 1 | B14: SCRAP POWER TRANSFORMER | C14: 3857116 | D14: 21977 | E14: NO | F14: 2007 | G14: SHAR JAHAN TRADERS | H14: 3857116 | I14: 694281 | J14: 4551397 | K14: 91028 | L14: 3857.116 | M14: 102406.43 | N14: 1735.7022 | O14: 100670.73 | P14: 104528 | Q14: 0 | R14: 0 | S14: 4537897 | T14: 964279 | U14: 964279 | V14: 13.08.2026 | W14: 3573618 | X14: 3573618.9 | Y14: 13.08.2026 | Z14: 0 | AD14: -0.90570839 | AE14: DR2640100024 | AF14: 1800003196 | AG14: 17.08.2026
A15: 250 | B15: Scrap of empty oil Druam | C15: 543 | D15: 21977 | E15: NO | F15: 2008 | G15: HIND TRADERS | H15: 135750 | I15: 24435 | J15: 160185 | K15: 3204 | L15: 135.75 | M15: 3604.1625 | N15: 61.0875 | O15: 3543.075 | P15: 3679 | Q15: 0 | R15: 0 | S15: 159710 | T15: 33938 | U15: 33938 | V15: 14.08.2026 | W15: 125772 | X15: 125772 | Y15: 18.08.2026 | Z15: 0 | AD15: 0 | AE15: DR2640100026 | AF15: 1800003247 | AG15: 20.08.2026
... A26: 2 | B26: Scrap of 132 KV Wave Trap | C26: 14001 | D26: 21978 | E26: NO | F26: 2035 | G26: NATIONAL ENTERPRISES | H26: 28002 | I26: 5040 | J26: 33042 | K26: 661 | L26: 28.002 | M26: 743.4531 | N26: 12.6009 | O26: 730.8522 | P26: 759 | Q26: 0 | R26: 0 | S26: 32944 | T26: 7001 | U26: 7001 | V26: 13.08.2026 | W26: 25944 | X26: 25943 | Y26: 24.08.2026 | Z26: 0 | AD26: 0 | AE26: DR2640100037 | AF26: 1800003310 | AG26: 27.08.2026
A27: 8.2 | B27: Mix Scrap (Tower angles & 0.2 ACSR Condutor pieces) | C27: 67000 | D27: 21978 | E27: MT | F27: 2036 | G27: M I SCRAP TRADERS | H27: 549400 | I27: 98892 | J27: 648292 | K27: 12966 | L27: 549.4 | M27: 14586.57 | N27: 247.23 | O27: 14339.34 | P27: 14889 | Q27: 0.02 | R27: 10988 | S27: 635381 | T27: 137350 | U27: 137350 | V27: 14.08.2026 | W27: 498031 | Y27: 0 | Z27: 19448.76 | AD27: 498031
A28: 50 | B28: Scrap of empty oil Barrels | C28: 531 | D28: 21978 | E28: NO | F28: 2037 | G28: WATAN SCRAP TRADERS | H28: 26550 | I28: 4779 | J28: 31329 | K28: 627 | L28: 26.55 | M28: 704.9025 | N28: 11.9475 | O28: 692.955 | P28: 720 | Q28: 0 | R28: 0 | S28: 31236 | T28: 6638 | U28: 6638 | V28: 14.08.2026 | W28: 24599 | X28: 24598 | Y28: 21.08.2026 | Z28: 0 | AD28: 0 | AE28: DR2640100043 | AF28: 1800003318 | AG28: 27.08.2026
A29: 3 | B29: Scrap of 33 KV CT | C29: 90002 | D29: 21978 | E29: NO | F29: 2040 | G29: STERLING ENTERPRISES | H29: 270006 | I29: 48601 | J29: 318607 | K29: 6372 | L29: 270.006 | M29: 7168.6593 | N29: 121.5027 | O29: 7047.1566 | P29: 7317 | Q29: 0 | R29: 0 | S29: 317662 | T29: 67502 | U29: 67502 | V29: 11.08.2026 | W29: 250161 | Y29: 0 | Z29: 9558.2124 | AD29: 250160
A30: 5 | B30: Scrap of 132 KV CT | C30: 80000 | D30: 21979 | E30: NO | F30: 2043 | G30: NATIONAL ENTERPRISES | H30: 400000 | I30: 72000 | J30: 472000 | K30: 9440 | L30: 400 | M30: 10620 | N30: 180 | O30: 10440 | P30: 10840 | Q30: 0 | R30: 0 | S30: 470600 | T30: 100000 | U30: 100000 | V30: 13.08.2026 | W30: 370600 | X30: 370600 | Y30: 24.08.2026 | Z30: 0 | AD30: 0 | AE30: DR2640100038 | AF30: 1800003311 | AG30: 27.08.2026
